File: ExpDat_60CP60012CoPU3GPM-1C.txt
#EXPORTTYPE:DATA ALL
#FILE:60CP60012CoPU3GPM-1C.ngb-ss4
#FORMAT:NETZSCH5
#FTYPE:ANSI
#IDENTITY:60CP60012CoPU3GPM-1C
#DECIMAL:POINT
#SEPARATOR:SEMICOLON
#MTYPE:DTA
#INSTRUMENT:NETZSCH STA 2500
#PROJECT:HÉCTOR ROMERO
#DATE/TIME:05.02.2020 11:55
#CORR. FILE:
#TEMPCAL:cal prueba.ngb-ts4
#SENSITIVITY:prueba cal sensibilidad.ngb-es4
#LABORATORY:ESIQIE
#OPERATOR:wendynoemi
#REMARK:
#SAMPLE:60CP60012CoPU3GPM-1C
#SAMPLE MASS /mg:4.910
#MATERIAL:ALUMINA
#REFERENCE:Crisol+Alumina
#REFERENCE MASS /mg:14.783
#TYPE OF CRUCIBLE:Al2O3 pan for STA2500
#SAMPLE CRUCIBLE MASS /mg:37.990
#REFERENCE CRUCIBLE MASS /mg:43.950
#TG RANGE /mg:500
#TAU-R:---
#CORR. CODE:000
#EXO:-1
#RANGE:20°C....700°C/-10.0....10.0K/min
#SEGMENT:S1-4/4
#SEG. 1:20°C/10.0(K/min)/150°C
#SEG. 2:150°C/00:30/150°C
#SEG. 3:150°C/10.0(K/min)/30°C
#SEG. 4:30°C/3.0(K/min)/700°C

##Temp./°C;Time/min;DTA/(mW/mg);Mass/%;Gas Flow(purge1)/(ml/min);Gas Flow(purge2)/(ml/min);Gas Flow(protective)/(ml/min);DTG/(%/min);Sensit./(uV/mW);Segment
 21.41200;  0.00000; 5.95931;100.00000; 0.000000e+000;      75.00000;75.00000;       1.63426;0.92259;1
 24.35700;  0.75000; 6.17692; 99.73051; 0.000000e+000;      75.00000;75.00000;      -1.56940;0.92593;1
 31.67300;  1.50000; 6.22634; 99.21067; 0.000000e+000;      75.00000;75.00000;      -1.11105;0.93408;1
 40.19800;  2.25000; 6.24087; 99.25385; 0.000000e+000;      75.00000;75.00000;      -0.44011;0.94328;1
 48.49200;  3.00000; 6.31316; 99.18420; 0.000000e+000;      75.00000;75.00000;      -0.52659;0.95193;1
 56.36500;  3.75000; 6.38886; 99.33637; 0.000000e+000;      75.00000;75.00000;       0.67014;0.95984;1
 63.97600;  4.50000; 6.46423; 99.27625; 0.000000e+000;      75.00000;75.00000;      -0.92848;0.96720;1
 71.48300;  5.25000; 6.52727; 99.36847; 0.000000e+000;      75.00000;75.00000;      -0.40774;0.97419;1
 78.99100;  6.00000; 6.59020; 99.41971; 0.000000e+000;      75.00000;75.00000;-6.887109e-002;0.98090;1
 86.55000;  6.75000; 6.64874; 99.42819; 0.000000e+000;      75.00000;75.00000;      -0.32160;0.98736;1
 94.12400;  7.50000; 6.70470; 99.55210; 0.000000e+000;      75.00000;75.00000;       1.05191;0.99353;1
101.70100;  8.25000; 6.75752; 99.62705; 0.000000e+000;      75.00000;75.00000;       0.17112;0.99940;1
109.18900;  9.00000; 6.81042; 99.64407; 0.000000e+000;      75.00000;75.00000;      -0.48846;1.00490;1
116.67200;  9.75000; 6.84796; 99.71128; 0.000000e+000;      75.00000;75.00000;       0.30862;1.01008;1
124.17800; 10.50000; 6.89589; 99.79992; 0.000000e+000;      75.00000;75.00000;      -0.61740;1.01495;1
131.70500; 11.25000; 6.94502; 99.80383; 0.000000e+000;      75.00000;75.00000; 3.330411e-002;1.01952;1
139.24500; 12.00000; 6.99850; 99.82167; 0.000000e+000;      75.00000;75.00000;       0.17812;1.02376;1
146.80701; 12.75000; 7.04378; 99.86444; 0.000000e+000;      75.00000;75.00000;      -0.26621;1.02768;1
152.28702; 13.50000; 7.17929; 99.94179; 0.000000e+000;      75.00000;75.00000;-9.576611e-002;1.03031;2
152.11483; 14.25000; 7.34758; 99.95346; 0.000000e+000;      75.00000;75.00000;       0.20631;1.03023;2
150.99426; 15.00000; 7.34725;100.09124; 0.000000e+000;      75.00000;75.00000;       0.22771;1.02970;2
150.29677; 15.75000; 7.29809;100.17741; 0.000000e+000;      75.00000;75.00000;       0.28956;1.02937;2
150.05012; 16.50000; 7.24467;100.25948; 0.000000e+000;      75.00000;75.00000; 7.442783e-002;1.02926;2
149.99443; 17.25000; 7.20878;100.30608; 0.000000e+000;      75.00000;75.00000;       0.13254;1.02923;2
150.03862; 18.00000; 7.18421;100.36507; 0.000000e+000;      75.00000;75.00000; 7.904151e-002;1.02925;2
150.05231; 18.75000; 7.16969;100.47465; 0.000000e+000;      75.00000;75.00000;       0.13930;1.02926;2
150.05530; 19.50000; 7.15774;100.52441; 0.000000e+000;      75.00000;75.00000;       0.11479;1.02926;2
150.06281; 20.25000; 7.14749;100.61259; 0.000000e+000;      75.00000;75.00000; 8.971216e-002;1.02926;2
150.05331; 21.00000; 7.13865;100.61941; 0.000000e+000;      75.00000;75.00000;       0.11591;1.02926;2
150.02761; 21.75000; 7.13044;100.71919; 0.000000e+000;      75.00000;75.00000;-5.443786e-002;1.02925;2
150.02013; 22.50000; 7.12527;100.77968; 0.000000e+000;      75.00000;75.00000;       0.22832;1.02924;2
150.04599; 23.25000; 7.11963;100.92893; 0.000000e+000;      75.00000;75.00000;-3.729110e-002;1.02926;2
150.01548; 24.00000; 7.11629;100.93355; 0.000000e+000;      75.00000;75.00000; 8.249329e-002;1.02924;2
150.02636; 24.75000; 7.11322;100.95120; 0.000000e+000;      75.00000;75.00000; 9.561647e-002;1.02925;2
150.04485; 25.50000; 7.11074;101.08448; 0.000000e+000;      75.00000;75.00000;-1.413819e-002;1.02926;2
150.02215; 26.25000; 7.11053;101.06531; 0.000000e+000;      75.00000;75.00000; 9.985705e-003;1.02924;2
150.02547; 27.00000; 7.10658;101.20471; 0.000000e+000;      75.00000;75.00000; 3.546502e-002;1.02925;2
150.04652; 27.75000; 7.10344;101.21541; 0.000000e+000;      75.00000;75.00000; 2.556479e-002;1.02926;2
150.01389; 28.50000; 7.10393;101.30232; 0.000000e+000;      75.00000;75.00000;       0.13469;1.02924;2
150.00193; 29.25000; 7.10422;101.33374; 0.000000e+000;      75.00000;75.00000;       0.14479;1.02923;2
150.03533; 30.00000; 7.10220;101.39886; 0.000000e+000;      75.00000;75.00000;       0.10101;1.02925;2
149.99610; 30.75000; 7.10295;101.48118; 0.000000e+000;      75.00000;75.00000; 9.478011e-002;1.02923;2
150.01046; 31.50000; 7.10413;101.56876; 0.000000e+000;      75.00000;75.00000;       0.16457;1.02924;2
150.01483; 32.25000; 7.10304;101.56413; 0.000000e+000;      75.00000;75.00000;      -0.10861;1.02924;2
150.01722; 33.00000; 7.10221;101.65858; 0.000000e+000;      75.00000;75.00000;       0.15239;1.02924;2
150.00486; 33.75000; 7.10232;101.70983; 0.000000e+000;      75.00000;75.00000; 8.995608e-002;1.02924;2
149.99517; 34.50000; 7.10389;101.82464; 0.000000e+000;      75.00000;75.00000; 8.647967e-002;1.02923;2
150.01667; 35.25000; 7.09978;101.83017; 0.000000e+000;      75.00000;75.00000;       0.12805;1.02924;2
150.01108; 36.00000; 7.10000;101.92936; 0.000000e+000;      75.00000;75.00000;-3.920931e-002;1.02924;2
150.00467; 36.75000; 7.10336;101.98780; 0.000000e+000;      75.00000;75.00000; 4.200295e-002;1.02924;2
149.99875; 37.50000; 7.10029;102.00961; 0.000000e+000;      75.00000;75.00000;-5.209119e-002;1.02923;2
150.01128; 38.25000; 7.10043;102.03176; 0.000000e+000;      75.00000;75.00000; 6.358740e-002;1.02924;2
150.00275; 39.00000; 7.10001;102.07258; 0.000000e+000;      75.00000;75.00000;       0.10509;1.02924;2
150.00003; 39.75000; 7.09854;102.16223; 0.000000e+000;      75.00000;75.00000; 6.200131e-002;1.02923;2
150.00596; 40.50000; 7.10062;102.20850; 0.000000e+000;      75.00000;75.00000;      -0.11772;1.02924;2
150.01841; 41.25000; 7.10108;102.24974; 0.000000e+000;      75.00000;75.00000; 5.187226e-002;1.02924;2
150.00811; 42.00000; 7.10119;102.29536; 0.000000e+000;      75.00000;75.00000;      -0.10606;1.02924;2
149.99828; 42.75000; 7.10020;102.27395; 0.000000e+000;      75.00000;75.00000;       0.16058;1.02923;2
148.13335; 43.50000; 7.16775;102.36970; 0.000000e+000;      75.00000;75.00000;       0.22094;1.02833;3
140.56444; 44.25000; 7.25485;102.43179; 0.000000e+000;      75.00000;75.00000;-9.749966e-002;1.02447;3
132.07197; 45.00000; 7.20568;102.44197; 0.000000e+000;      75.00000;75.00000;      -1.35212;1.01973;3
123.93404; 45.75000; 7.10807;102.52382; 0.000000e+000;      75.00000;75.00000;      -0.91991;1.01480;3
116.27297; 46.50000; 7.00053;102.58727; 0.000000e+000;      75.00000;75.00000;       0.74153;1.00981;3
109.31264; 47.25000; 6.89715;102.65016; 0.000000e+000;      75.00000;75.00000;       1.00292;1.00498;3
103.02506; 48.00000; 6.80786;102.72954; 0.000000e+000;      75.00000;75.00000;       0.17393;1.00040;3
 97.31507; 48.75000; 6.73091;102.78496; 0.000000e+000;      75.00000;75.00000;       0.63509;0.99604;3
 92.13546; 49.50000; 6.66400;102.74157; 5.454304e-315;      75.00000;75.00000;-1.213781e-002;0.99194;3
 87.37353; 50.25000; 6.60976;102.84705;-4.293440e-272;      75.00000;75.00000;       0.37436;0.98805;3
 82.98527; 51.00000; 6.56385;102.83217; 3.379648e-229;      75.00000;75.00000;      -0.67735;0.98435;3
 78.94263; 51.75000; 6.51897;102.91893;-2.660342e-186;      75.00000;75.00000;       1.17530;0.98086;3
 75.18568; 52.50000; 6.48140;102.94500; 2.094130e-143;      75.00000;75.00000;      -0.17965;0.97754;3
 71.65851; 53.25000; 6.44770;103.01680;-1.648427e-100;      75.00000;75.00000;       0.40295;0.97435;3
 68.34556; 54.00000; 6.41651;103.01854; 1.297585e-057;      75.00000;75.00000;-1.156962e-002;0.97131;3
 65.30334; 54.75000; 6.38743;103.15348;-1.021414e-014;      75.00000;75.00000;       1.00018;0.96846;3
 62.45666; 55.50000; 6.29724;103.23699;      75.00000;-6.976137e-017;75.00000;       0.32744;0.96576;4
 59.76295; 56.25000; 6.32197;103.29666;      75.00000; 1.276366e-042;75.00000;      -0.79129;0.96316;4
 57.25907; 57.00000; 6.31691;103.33310;      75.00000;-2.335263e-068;75.00000;       0.14036;0.96072;4
 54.93701; 57.75000; 6.29716;103.36037;      75.00000; 4.272638e-094;75.00000;      -0.25965;0.95842;4
 52.76805; 58.50000; 6.27828;103.45905;      75.00000;-7.817294e-120;75.00000;       0.11122;0.95626;4
 50.72852; 59.25000; 6.26065;103.45486;      75.00000; 1.430266e-145;75.00000;      -0.39157;0.95420;4
 48.82552; 60.00000; 6.24352;103.50061;      75.00000;-2.616840e-171;75.00000;       0.70137;0.95227;4
 47.06128; 60.75000; 6.22877;103.54212;      75.00000; 4.787817e-197;75.00000;      -0.60339;0.95046;4
 45.38207; 61.50000; 6.21431;103.59594;      75.00000;-8.759874e-223;75.00000;       0.99387;0.94872;4
 43.84979; 62.25000; 6.20130;103.70838;      75.00000; 1.602722e-248;75.00000; 1.320354e-002;0.94713;4
 45.89667; 63.00000; 6.18421;103.72350;      75.00000;-2.932369e-274;75.00000;       0.31359;0.94926;4
 51.96044; 63.75000; 6.20377;103.67335;      75.00000; 5.365114e-300;75.00000;       0.47970;0.95545;4
 57.01237; 64.50000; 6.28600;103.77312;      75.00000; 0.000000e+000;75.00000;       0.29903;0.96047;4
 60.42702; 65.25000; 6.36634;103.83624;      75.00000; 0.000000e+000;75.00000;      -0.28023;0.96380;4
 62.91873; 66.00000; 6.42425;103.83144;      75.00000; 0.000000e+000;75.00000;       0.97563;0.96620;4
 65.06073; 66.75000; 6.46114;103.88202;      75.00000; 0.000000e+000;75.00000;      -0.26097;0.96823;4
 67.19306; 67.50000; 6.48645;103.90227;      75.00000; 0.000000e+000;75.00000;-6.910601e-002;0.97023;4
 69.38673; 68.25000; 6.50963;103.91992;      75.00000; 0.000000e+000;75.00000;      -0.48304;0.97227;4
 71.62656; 69.00000; 6.53206;103.98738;      75.00000; 0.000000e+000;75.00000;       0.80195;0.97432;4
 73.88762; 69.75000; 6.55127;104.04415;      75.00000; 0.000000e+000;75.00000;      -0.28113;0.97637;4
 76.16048; 70.50000; 6.57154;103.99403;      75.00000; 0.000000e+000;75.00000;      -0.31461;0.97840;4
 78.39265; 71.25000; 6.59387;104.10021;      75.00000; 0.000000e+000;75.00000;      -0.30333;0.98038;4
 80.64833; 72.00000; 6.61262;104.09840;      75.00000; 0.000000e+000;75.00000;       0.80232;0.98234;4
 82.90653; 72.75000; 6.63032;104.18448;      75.00000; 0.000000e+000;75.00000;      -0.41928;0.98428;4
 85.16448; 73.50000; 6.64849;104.19947;      75.00000; 0.000000e+000;75.00000;      -0.73715;0.98620;4
 87.43748; 74.25000; 6.66465;104.21849;      75.00000; 0.000000e+000;75.00000;       0.38411;0.98810;4
 89.69548; 75.00000; 6.68125;104.31895;      75.00000; 0.000000e+000;75.00000;       0.56990;0.98996;4
 91.95113; 75.75000; 6.69700;104.28604;      75.00000; 0.000000e+000;75.00000;       0.10487;0.99179;4
 94.22202; 76.50000; 6.71476;104.34034;      75.00000; 0.000000e+000;75.00000;      -0.36707;0.99361;4
 96.47603; 77.25000; 6.73027;104.40271;      75.00000; 0.000000e+000;75.00000; 4.278164e-002;0.99539;4
 98.73496; 78.00000; 6.74551;104.36982;      75.00000; 0.000000e+000;75.00000;       0.46724;0.99714;4
100.97258; 78.75000; 6.75906;104.50966;      75.00000; 0.000000e+000;75.00000;-9.509932e-002;0.99885;4
103.24027; 79.50000; 6.77393;104.53133;      75.00000; 0.000000e+000;75.00000;      -0.49177;1.00056;4
105.48112; 80.25000; 6.78724;104.56522;      75.00000; 0.000000e+000;75.00000;      -0.16227;1.00222;4
107.72051; 81.00000; 6.80219;104.54242;      75.00000; 0.000000e+000;75.00000;      -0.14469;1.00384;4
109.95526; 81.75000; 6.81442;104.61469;      75.00000; 0.000000e+000;75.00000;       0.65478;1.00544;4
112.23180; 82.50000; 6.82694;104.63191;      75.00000; 0.000000e+000;75.00000;       0.82433;1.00704;4
114.47704; 83.25000; 6.84212;104.69947;      75.00000; 0.000000e+000;75.00000;       0.20348;1.00859;4
116.72285; 84.00000; 6.85478;104.71268;      75.00000; 0.000000e+000;75.00000;      -0.75369;1.01011;4
118.95037; 84.75000; 6.86808;104.77004;      75.00000; 0.000000e+000;75.00000;      -0.22743;1.01159;4
121.21679; 85.50000; 6.88077;104.80250;      75.00000; 0.000000e+000;75.00000;      -0.40578;1.01307;4
123.49127; 86.25000; 6.89301;104.78502;      75.00000; 0.000000e+000;75.00000;-8.677948e-003;1.01452;4
125.72389; 87.00000; 6.90782;104.84309;      75.00000; 0.000000e+000;75.00000;       0.75702;1.01592;4
127.98859; 87.75000; 6.92468;104.83943;      75.00000; 0.000000e+000;75.00000;      -0.55519;1.01730;4
130.23724; 88.50000; 6.94083;104.94484;      75.00000; 0.000000e+000;75.00000;-6.563210e-002;1.01865;4
132.47975; 89.25000; 6.95550;104.94636;      75.00000; 0.000000e+000;75.00000;      -0.27996;1.01997;4
134.72923; 90.00000; 6.96845;104.98917;      75.00000; 0.000000e+000;75.00000;-1.342205e-002;1.02126;4
136.99555; 90.75000; 6.98289;104.98972;      75.00000; 0.000000e+000;75.00000;       1.09858;1.02253;4
139.24985; 91.50000; 6.99580;105.01821;      75.00000; 0.000000e+000;75.00000;       0.18033;1.02376;4
141.49094; 92.25000; 7.01149;105.00089;      75.00000; 0.000000e+000;75.00000;      -0.19026;1.02496;4
143.74309; 93.00000; 7.02648;105.05610;      75.00000; 0.000000e+000;75.00000; 5.777029e-002;1.02613;4
146.01498; 93.75000; 7.03726;105.10733;      75.00000; 0.000000e+000;75.00000;      -0.51337;1.02729;4
148.25852; 94.50000; 7.04626;105.12126;      75.00000; 0.000000e+000;75.00000;       0.37134;1.02839;4
150.51363; 95.25000; 7.05877;105.21929;      75.00000; 0.000000e+000;75.00000;      -0.73285;1.02948;4
152.76041; 96.00000; 7.07134;105.22852;      75.00000; 0.000000e+000;75.00000;       0.89296;1.03053;4
155.00928; 96.75000; 7.08079;105.24446;      75.00000; 0.000000e+000;75.00000;      -0.54904;1.03155;4
157.25767; 97.50000; 7.08694;105.27496;      75.00000; 0.000000e+000;75.00000;      -0.35155;1.03253;4
159.51270; 98.25000; 7.09945;105.29619;      75.00000; 0.000000e+000;75.00000;      -0.10764;1.03350;4
161.75115; 99.00000; 7.11026;105.43364;      75.00000; 0.000000e+000;75.00000;       0.52197;1.03442;4
164.00347; 99.75000; 7.12073;105.41700;      75.00000; 0.000000e+000;75.00000;       0.46417;1.03532;4
166.25108;100.50000; 7.13138;105.39333;      75.00000; 0.000000e+000;75.00000;-8.890810e-002;1.03618;4
168.48161;101.25000; 7.13970;105.44710;      75.00000; 0.000000e+000;75.00000;-3.928412e-002;1.03701;4
170.74239;102.00000; 7.14535;105.45764;      75.00000; 0.000000e+000;75.00000; 2.286613e-002;1.03782;4
173.00307;102.75000; 7.15242;105.55204;      75.00000; 0.000000e+000;75.00000;       0.34114;1.03860;4
175.26809;103.50000; 7.15924;105.61181;      75.00000; 0.000000e+000;75.00000;       1.02959;1.03934;4
177.52521;104.25000; 7.16732;105.55748;      75.00000; 0.000000e+000;75.00000;      -0.68417;1.04006;4
179.78779;105.00000; 7.17487;105.57548;      75.00000; 0.000000e+000;75.00000;      -0.63754;1.04074;4
182.02165;105.75000; 7.17788;105.63373;      75.00000; 0.000000e+000;75.00000;       0.48749;1.04138;4
184.26822;106.50000; 7.18216;105.69697;      75.00000; 0.000000e+000;75.00000;-7.121859e-002;1.04200;4
186.51888;107.25000; 7.18323;105.65119;      75.00000; 0.000000e+000;75.00000;      -0.36359;1.04258;4
188.77451;108.00000; 7.18673;105.72427;      75.00000; 0.000000e+000;75.00000;-8.705284e-002;1.04313;4
191.03986;108.75000; 7.18622;105.64228;      75.00000; 0.000000e+000;75.00000;      -0.26014;1.04366;4
193.27748;109.50000; 7.18703;105.69594;      75.00000; 0.000000e+000;75.00000;-6.185827e-003;1.04414;4
195.52614;110.25000; 7.18388;105.78452;      75.00000; 0.000000e+000;75.00000;       0.45330;1.04460;4
197.77776;111.00000; 7.18544;105.82936;      75.00000; 0.000000e+000;75.00000;       0.45480;1.04503;4
200.02103;111.75000; 7.18629;105.78796;      75.00000; 0.000000e+000;75.00000;      -0.66827;1.04542;4
202.27243;112.50000; 7.19093;105.76921;      75.00000; 0.000000e+000;75.00000;      -0.63385;1.04578;4
204.53743;113.25000; 7.19966;105.85396;      75.00000; 0.000000e+000;75.00000;       0.52129;1.04611;4
206.77924;114.00000; 7.21210;105.83198;      75.00000; 0.000000e+000;75.00000; 8.140487e-002;1.04641;4
209.02722;114.75000; 7.22956;105.89881;      75.00000; 0.000000e+000;75.00000;      -0.46025;1.04667;4
211.28608;115.50000; 7.24951;105.87898;      75.00000; 0.000000e+000;75.00000;      -0.29737;1.04691;4
213.53321;116.25000; 7.27218;105.87012;      75.00000; 0.000000e+000;75.00000;      -0.19223;1.04711;4
215.79205;117.00000; 7.29579;105.95649;      75.00000; 0.000000e+000;75.00000;      -0.40596;1.04728;4
218.02074;117.75000; 7.31620;105.94110;      75.00000; 0.000000e+000;75.00000;      -0.20285;1.04742;4
220.27607;118.50000; 7.33557;106.00410;      75.00000; 0.000000e+000;75.00000;       0.62992;1.04752;4
222.54027;119.25000; 7.34744;105.96031;      75.00000; 0.000000e+000;75.00000;      -0.61858;1.04759;4
224.78647;120.00000; 7.36254;106.01266;      75.00000; 0.000000e+000;75.00000;       0.31041;1.04764;4
227.03067;120.75000; 7.37335;105.99862;      75.00000; 0.000000e+000;75.00000;      -0.28592;1.04764;4
229.28100;121.50000; 7.38226;106.12679;      75.00000; 0.000000e+000;75.00000;       0.59150;1.04762;4
231.52557;122.25000; 7.39510;106.09816;      75.00000; 0.000000e+000;75.00000;       0.51983;1.04756;4
233.79085;123.00000; 7.40686;106.08866;      75.00000; 0.000000e+000;75.00000;       0.49475;1.04748;4
236.03518;123.75000; 7.41824;106.21603;      75.00000; 0.000000e+000;75.00000; 3.291169e-002;1.04736;4
238.28088;124.50000; 7.42795;106.21872;      75.00000; 0.000000e+000;75.00000;      -0.34743;1.04720;4
240.53937;125.25000; 7.43948;106.28063;      75.00000; 0.000000e+000;75.00000;       0.29353;1.04702;4
242.79411;126.00000; 7.45217;106.28159;      75.00000; 0.000000e+000;75.00000;      -0.11092;1.04680;4
245.03324;126.75000; 7.46239;106.24906;      75.00000; 0.000000e+000;75.00000;       0.75293;1.04655;4
247.29230;127.50000; 7.47600;106.26908;      75.00000; 0.000000e+000;75.00000;       0.35313;1.04627;4
249.54870;128.25000; 7.48744;106.34725;      75.00000; 0.000000e+000;75.00000;       0.36129;1.04596;4
251.79583;129.00000; 7.49900;106.34362;      75.00000; 0.000000e+000;75.00000;      -0.45154;1.04561;4
254.04745;129.75000; 7.51210;106.37175;      75.00000; 0.000000e+000;75.00000;       0.47135;1.04523;4
256.30139;130.50000; 7.52204;106.35388;      75.00000; 0.000000e+000;75.00000;       0.45041;1.04482;4
258.54888;131.25000; 7.53343;106.40677;      75.00000; 0.000000e+000;75.00000; 4.474156e-002;1.04438;4
260.78780;132.00000; 7.54067;106.43732;      75.00000; 0.000000e+000;75.00000;       0.23838;1.04391;4
263.04422;132.75000; 7.55429;106.43160;      75.00000; 0.000000e+000;75.00000;-1.115769e-002;1.04340;4
265.29541;133.50000; 7.56255;106.47855;      75.00000; 0.000000e+000;75.00000;      -0.28475;1.04287;4
267.53822;134.25000; 7.57022;106.48461;      75.00000; 0.000000e+000;75.00000;      -0.36562;1.04230;4
269.79626;135.00000; 7.58298;106.57676;      75.00000; 0.000000e+000;75.00000; 6.989235e-002;1.04170;4
272.04353;135.75000; 7.59145;106.59904;      75.00000; 0.000000e+000;75.00000;-7.009268e-002;1.04106;4
274.28199;136.50000; 7.60120;106.69357;      75.00000; 0.000000e+000;75.00000;       0.72505;1.04040;4
276.55056;137.25000; 7.60823;106.62523;      75.00000; 0.000000e+000;75.00000;       0.47981;1.03970;4
278.77887;138.00000; 7.62043;106.54969;      75.00000; 0.000000e+000;75.00000;      -0.52905;1.03898;4
281.03564;138.75000; 7.62896;106.63095;      75.00000; 0.000000e+000;75.00000;      -0.32964;1.03822;4
283.29272;139.50000; 7.63752;106.59959;      75.00000; 0.000000e+000;75.00000;       0.84857;1.03743;4
285.54576;140.25000; 7.64503;106.73808;      75.00000; 0.000000e+000;75.00000;      -0.46083;1.03661;4
287.79900;141.00000; 7.65316;106.76856;      75.00000; 0.000000e+000;75.00000; 1.688767e-003;1.03575;4
290.04183;141.75000; 7.66181;106.75015;      75.00000; 0.000000e+000;75.00000;      -0.35965;1.03487;4
292.30241;142.50000; 7.66762;106.74366;      75.00000; 0.000000e+000;75.00000;      -0.30054;1.03395;4
294.53637;143.25000; 7.67545;106.71510;      75.00000; 0.000000e+000;75.00000; 7.699384e-002;1.03301;4
296.80575;144.00000; 7.67633;106.85979;      75.00000; 0.000000e+000;75.00000;       0.36998;1.03202;4
299.06334;144.75000; 7.68355;106.78389;      75.00000; 0.000000e+000;75.00000;       0.57210;1.03101;4
301.29341;145.50000; 7.68790;106.80802;      75.00000; 0.000000e+000;75.00000; 9.500346e-002;1.02998;4
303.55951;146.25000; 7.68891;106.87292;      75.00000; 0.000000e+000;75.00000;      -0.23370;1.02890;4
305.80648;147.00000; 7.69193;106.85429;      75.00000; 0.000000e+000;75.00000;       0.55051;1.02781;4
308.06529;147.75000; 7.69371;106.83228;      75.00000; 0.000000e+000;75.00000;       0.57503;1.02667;4
310.30022;148.50000; 7.69290;106.80113;      75.00000; 0.000000e+000;75.00000;      -0.62504;1.02552;4
312.54461;149.25000; 7.69234;106.80030;      75.00000; 0.000000e+000;75.00000;      -0.32094;1.02433;4
314.80947;150.00000; 7.68849;106.78164;      75.00000; 0.000000e+000;75.00000;      -0.83581;1.02310;4
317.04736;150.75000; 7.68417;106.75682;      75.00000; 0.000000e+000;75.00000;       1.14452;1.02185;4
319.29225;151.50000; 7.67816;106.79359;      75.00000; 0.000000e+000;75.00000; 2.007772e-002;1.02057;4
321.54735;152.25000; 7.67184;106.73350;      75.00000; 0.000000e+000;75.00000;      -0.40693;1.01926;4
323.79773;153.00000; 7.65914;106.74625;      75.00000; 0.000000e+000;75.00000;       0.10315;1.01791;4
326.05993;153.75000; 7.64305;106.70805;      75.00000; 0.000000e+000;75.00000;       0.84618;1.01654;4
328.30222;154.50000; 7.62723;106.60442;      75.00000; 0.000000e+000;75.00000;      -0.68935;1.01514;4
330.54719;155.25000; 7.60024;106.52980;      75.00000; 0.000000e+000;75.00000;      -0.16610;1.01371;4
332.82006;156.00000; 7.57723;106.57682;      75.00000; 0.000000e+000;75.00000;      -0.58831;1.01224;4
335.06721;156.75000; 7.55026;106.41334;      75.00000; 0.000000e+000;75.00000;-9.859122e-002;1.01075;4
337.29870;157.50000; 7.52263;106.35308;      75.00000; 0.000000e+000;75.00000;      -0.14536;1.00924;4
339.53859;158.25000; 7.48708;106.24447;      75.00000; 0.000000e+000;75.00000;       0.75656;1.00770;4
341.81948;159.00000; 7.44693;106.23810;      75.00000; 0.000000e+000;75.00000;       0.30128;1.00610;4
344.05946;159.75000; 7.40882;106.04653;      75.00000; 0.000000e+000;75.00000;       0.18814;1.00451;4
346.30256;160.50000; 7.36633;105.89723;      75.00000; 0.000000e+000;75.00000;       0.28008;1.00288;4
348.55042;161.25000; 7.32212;105.73336;      75.00000; 0.000000e+000;75.00000;      -0.63257;1.00122;4
350.80907;162.00000; 7.27025;105.52737;      75.00000; 0.000000e+000;75.00000;      -0.11582;0.99952;4
353.05592;162.75000; 7.22311;105.43010;      75.00000; 0.000000e+000;75.00000; 8.491688e-002;0.99781;4
355.32131;163.50000; 7.17800;105.25123;      75.00000; 0.000000e+000;75.00000;       0.36007;0.99605;4
357.55814;164.25000; 7.13147;105.02421;      75.00000; 0.000000e+000;75.00000;       0.24069;0.99429;4
359.81867;165.00000; 7.08214;104.83600;      75.00000; 0.000000e+000;75.00000;       0.27314;0.99248;4
362.06367;165.75000; 7.04331;104.60543;      75.00000; 0.000000e+000;75.00000;       0.18265;0.99065;4
364.30471;166.50000; 7.00652;104.38654;      75.00000; 0.000000e+000;75.00000;      -0.68719;0.98880;4
366.56357;167.25000; 6.97833;104.15366;      75.00000; 0.000000e+000;75.00000;      -0.81934;0.98691;4
368.79973;168.00000; 6.95781;103.79457;      75.00000; 0.000000e+000;75.00000;      -0.85019;0.98501;4
371.06737;168.75000; 6.94653;103.56199;      75.00000; 0.000000e+000;75.00000;-9.672133e-002;0.98306;4
373.29959;169.50000; 6.94421;103.33362;      75.00000; 0.000000e+000;75.00000;      -0.35126;0.98111;4
375.55698;170.25000; 6.95118;103.05149;      75.00000; 0.000000e+000;75.00000;      -0.91426;0.97912;4
377.80657;171.00000; 6.97122;102.66113;      75.00000; 0.000000e+000;75.00000;      -0.13594;0.97710;4
380.04923;171.75000; 7.00764;102.39130;      75.00000; 0.000000e+000;75.00000;      -0.79406;0.97507;4
382.31749;172.50000; 7.05282;102.21663;      75.00000; 0.000000e+000;75.00000;      -0.38477;0.97298;4
384.57023;173.25000; 7.12205;101.88819;      75.00000; 0.000000e+000;75.00000;      -0.69556;0.97088;4
386.82179;174.00000; 7.20824;101.55829;      75.00000; 0.000000e+000;75.00000;      -0.29968;0.96876;4
389.06383;174.75000; 7.29832;101.33785;      75.00000; 0.000000e+000;75.00000;      -0.50365;0.96662;4
391.30944;175.50000; 7.40614;101.03088;      75.00000; 0.000000e+000;75.00000;      -0.98281;0.96446;4
393.56077;176.25000; 7.52575;100.82856;      75.00000; 0.000000e+000;75.00000;      -0.92240;0.96226;4
395.79325;177.00000; 7.65847;100.56507;      75.00000; 0.000000e+000;75.00000;      -0.21600;0.96006;4
398.04670;177.75000; 7.79220;100.39575;      75.00000; 0.000000e+000;75.00000;-4.002230e-002;0.95781;4
400.30587;178.50000; 7.93278;100.17603;      75.00000; 0.000000e+000;75.00000;       0.19032;0.95553;4
402.56054;179.25000; 8.07531; 99.94234;      75.00000; 0.000000e+000;75.00000;      -0.20381;0.95323;4
404.79792;180.00000; 8.22135; 99.80126;      75.00000; 0.000000e+000;75.00000;-1.730350e-002;0.95093;4
407.05139;180.75000; 8.35468; 99.66000;      75.00000; 0.000000e+000;75.00000;      -0.22907;0.94858;4
409.28132;181.50000; 8.49715; 99.54315;      75.00000; 0.000000e+000;75.00000;       0.55026;0.94624;4
411.55984;182.25000; 8.63328; 99.40061;      75.00000; 0.000000e+000;75.00000;-8.341455e-002;0.94382;4
413.82558;183.00000; 8.76952; 99.36597;      75.00000; 0.000000e+000;75.00000; 2.819450e-002;0.94139;4
416.02627;183.75000; 8.90290; 99.23437;      75.00000; 0.000000e+000;75.00000;      -0.66087;0.93901;4
418.27442;184.50000; 9.01625; 99.17880;      75.00000; 0.000000e+000;75.00000;       0.13764;0.93655;4
420.56843;185.25000; 9.12400; 99.18854;      75.00000; 0.000000e+000;75.00000;      -0.70785;0.93402;4
422.80562;186.00000; 9.22667; 99.15239;      75.00000; 0.000000e+000;75.00000; 6.434704e-003;0.93153;4
425.05568;186.75000; 9.31993; 99.08400;      75.00000; 0.000000e+000;75.00000;      -0.43609;0.92901;4
427.31448;187.50000; 9.40656; 99.10750;      75.00000; 0.000000e+000;75.00000;      -0.33995;0.92645;4
429.57014;188.25000; 9.48783; 99.09200;      75.00000; 0.000000e+000;75.00000;       0.29321;0.92387;4
431.82851;189.00000; 9.55640; 99.05155;      75.00000; 0.000000e+000;75.00000;      -0.76917;0.92127;4
434.09369;189.75000; 9.63040; 99.09402;      75.00000; 0.000000e+000;75.00000;      -0.15892;0.91864;4
436.32923;190.50000; 9.69317; 99.15348;      75.00000; 0.000000e+000;75.00000;      -0.16462;0.91602;4
438.56877;191.25000; 9.75026; 99.11552;      75.00000; 0.000000e+000;75.00000; 9.908153e-002;0.91338;4
440.82425;192.00000; 9.80613; 99.15822;      75.00000; 0.000000e+000;75.00000; 4.556993e-002;0.91070;4
443.06973;192.75000; 9.85743; 99.11451;      75.00000; 0.000000e+000;75.00000;      -0.76069;0.90801;4
445.30454;193.50000; 9.90811; 99.16753;      75.00000; 0.000000e+000;75.00000;       0.23149;0.90531;4
447.56341;194.25000; 9.95617; 99.14458;      75.00000; 0.000000e+000;75.00000;       0.29408;0.90256;4
449.82222;195.00000;10.00244; 99.20304;      75.00000; 0.000000e+000;75.00000;      -0.99651;0.89979;4
452.07296;195.75000;10.05935; 99.14273;      75.00000; 0.000000e+000;75.00000;       0.58968;0.89702;4
454.31025;196.50000;10.10815; 99.20130;      75.00000; 0.000000e+000;75.00000; 4.978402e-002;0.89424;4
456.56284;197.25000;10.15991; 99.14277;      75.00000; 0.000000e+000;75.00000;       0.68268;0.89142;4
458.80736;198.00000;10.20830; 99.22894;      75.00000; 0.000000e+000;75.00000; 1.109027e-002;0.88859;4
461.06365;198.75000;10.25666; 99.22081;      75.00000; 0.000000e+000;75.00000;-8.347930e-002;0.88573;4
463.30744;199.50000;10.30705; 99.21676;      75.00000; 0.000000e+000;75.00000;      -0.14225;0.88287;4
465.56229;200.25000;10.35653; 99.16269;      75.00000; 0.000000e+000;75.00000;      -0.14248;0.87997;4
467.80656;201.00000;10.41183; 99.18292;      75.00000; 0.000000e+000;75.00000;      -0.52361;0.87707;4
470.08172;201.75000;10.46984; 99.18215;      75.00000; 0.000000e+000;75.00000;       0.23816;0.87412;4
472.30320;202.50000;10.52355; 99.20504;      75.00000; 0.000000e+000;75.00000;       0.46123;0.87121;4
474.56752;203.25000;10.57747; 99.25451;      75.00000; 0.000000e+000;75.00000;      -0.32915;0.86823;4
476.82317;204.00000;10.62418; 99.23548;      75.00000; 0.000000e+000;75.00000;       0.57038;0.86525;4
479.08166;204.75000;10.67688; 99.28549;      75.00000; 0.000000e+000;75.00000; 5.964405e-002;0.86224;4
481.31070;205.50000;10.73834; 99.31392;      75.00000; 0.000000e+000;75.00000;       0.86242;0.85926;4
483.57171;206.25000;10.78869; 99.36750;      75.00000; 0.000000e+000;75.00000; 1.273926e-002;0.85622;4
485.81689;207.00000;10.85637; 99.26590;      75.00000; 0.000000e+000;75.00000;       0.46118;0.85319;4
488.05781;207.75000;10.91357; 99.33532;      75.00000; 0.000000e+000;75.00000;      -0.30501;0.85014;4
490.31410;208.50000;10.97386; 99.29550;      75.00000; 0.000000e+000;75.00000; 4.675340e-002;0.84706;4
492.57244;209.25000;11.03955; 99.37354;      75.00000; 0.000000e+000;75.00000;       0.25712;0.84396;4
494.82452;210.00000;11.10229; 99.35627;      75.00000; 0.000000e+000;75.00000;       0.51740;0.84085;4
497.07384;210.75000;11.17088; 99.46373;      75.00000; 0.000000e+000;75.00000;-8.027664e-002;0.83773;4
499.31535;211.50000;11.23521; 99.40588;      75.00000; 0.000000e+000;75.00000;       0.54169;0.83461;4
501.55708;212.25000;11.29652; 99.41941;      75.00000; 0.000000e+000;75.00000;      -0.37019;0.83147;4
503.81772;213.00000;11.36460; 99.38792;      75.00000; 0.000000e+000;75.00000;       0.67042;0.82829;4
506.06751;213.75000;11.42900; 99.34775;      75.00000; 0.000000e+000;75.00000;      -0.35221;0.82512;4
508.32714;214.50000;11.49661; 99.35082;      75.00000; 0.000000e+000;75.00000;      -0.12036;0.82191;4
510.58068;215.25000;11.56441; 99.39830;      75.00000; 0.000000e+000;75.00000;      -0.48727;0.81870;4
512.84230;216.00000;11.63079; 99.48387;      75.00000; 0.000000e+000;75.00000;       0.70270;0.81547;4
515.07393;216.75000;11.69041; 99.45253;      75.00000; 0.000000e+000;75.00000;      -0.19317;0.81227;4
517.32786;217.50000;11.75762; 99.37453;      75.00000; 0.000000e+000;75.00000;      -0.26004;0.80902;4
519.58148;218.25000;11.83053; 99.46689;      75.00000; 0.000000e+000;75.00000;      -0.62064;0.80576;4
521.80239;219.00000;11.90265; 99.44715;      75.00000; 0.000000e+000;75.00000;-1.812922e-002;0.80253;4
524.07163;219.75000;11.97390; 99.45720;      75.00000; 0.000000e+000;75.00000;       0.14623;0.79923;4
526.34211;220.50000;12.05909; 99.48292;      75.00000; 0.000000e+000;75.00000;      -0.42088;0.79591;4
528.57815;221.25000;12.13323; 99.41021;      75.00000; 0.000000e+000;75.00000;       0.26995;0.79262;4
530.84059;222.00000;12.20766; 99.37566;      75.00000; 0.000000e+000;75.00000;       0.27120;0.78929;4
533.08554;222.75000;12.28468; 99.49387;      75.00000; 0.000000e+000;75.00000;       0.25073;0.78598;4
535.33563;223.50000;12.36305; 99.35652;      75.00000; 0.000000e+000;75.00000;      -0.35367;0.78264;4
537.58542;224.25000;12.44161; 99.45926;      75.00000; 0.000000e+000;75.00000;      -0.44948;0.77930;4
539.82175;225.00000;12.52868; 99.40649;      75.00000; 0.000000e+000;75.00000;      -0.14704;0.77596;4
542.11486;225.75000;12.61203; 99.43550;      75.00000; 0.000000e+000;75.00000;       0.15455;0.77253;4
544.36850;226.50000;12.72005; 99.40998;      75.00000; 0.000000e+000;75.00000;       0.11520;0.76915;4
546.58342;227.25000;12.81156; 99.45222;      75.00000; 0.000000e+000;75.00000;      -0.11437;0.76582;4
548.82978;228.00000;12.88763; 99.44636;      75.00000; 0.000000e+000;75.00000;       0.27067;0.76243;4
551.08794;228.75000;12.97902; 99.51586;      75.00000; 0.000000e+000;75.00000; 6.136584e-002;0.75901;4
553.32807;229.50000;13.06673; 99.43751;      75.00000; 0.000000e+000;75.00000;      -0.31086;0.75562;4
555.58050;230.25000;13.15982; 99.42585;      75.00000; 0.000000e+000;75.00000;      -0.15888;0.75219;4
557.82930;231.00000;13.24352; 99.47119;      75.00000; 0.000000e+000;75.00000;-3.440832e-002;0.74877;4
560.08409;231.75000;13.33390; 99.41470;      75.00000; 0.000000e+000;75.00000;       0.67191;0.74532;4
562.33520;232.50000;13.42641; 99.45326;      75.00000; 0.000000e+000;75.00000;       0.38408;0.74188;4
564.58859;233.25000;13.51824; 99.54127;      75.00000; 0.000000e+000;75.00000;-3.503804e-002;0.73842;4
566.83843;234.00000;13.61698; 99.47690;      75.00000; 0.000000e+000;75.00000;       0.18554;0.73496;4
569.10712;234.75000;13.71361; 99.51206;      75.00000; 0.000000e+000;75.00000;      -0.23436;0.73147;4
571.37316;235.50000;13.80851; 99.54105;      75.00000; 0.000000e+000;75.00000;       0.11998;0.72797;4
573.59415;236.25000;13.90667; 99.55232;      75.00000; 0.000000e+000;75.00000;       0.52238;0.72454;4
575.85730;237.00000;14.01323; 99.56712;      75.00000; 0.000000e+000;75.00000;       0.66263;0.72104;4
578.08470;237.75000;14.10734; 99.56839;      75.00000; 0.000000e+000;75.00000; 4.950896e-002;0.71758;4
580.33868;238.50000;14.21070; 99.49192;      75.00000; 0.000000e+000;75.00000;-2.461481e-002;0.71408;4
582.59164;239.25000;14.31694; 99.53157;      75.00000; 0.000000e+000;75.00000;      -0.44124;0.71057;4
584.85772;240.00000;14.42228; 99.60997;      75.00000; 0.000000e+000;75.00000;       0.66595;0.70704;4
587.10750;240.75000;14.54395; 99.62348;      75.00000; 0.000000e+000;75.00000;      -0.89024;0.70353;4
589.33771;241.50000;14.66373; 99.59019;      75.00000; 0.000000e+000;75.00000;       0.44953;0.70004;4
591.61851;242.25000;14.76373; 99.57188;      75.00000; 0.000000e+000;75.00000;-9.869252e-002;0.69647;4
593.86167;243.00000;14.88165; 99.53356;      75.00000; 0.000000e+000;75.00000;       0.18255;0.69295;4
596.09787;243.75000;14.98641; 99.54343;      75.00000; 0.000000e+000;75.00000;       0.59949;0.68945;4
598.36761;244.50000;15.09847; 99.57640;      75.00000; 0.000000e+000;75.00000; 6.767764e-002;0.68588;4
600.60620;245.25000;15.21341; 99.58323;      75.00000; 0.000000e+000;75.00000;      -0.24680;0.68236;4
602.84749;246.00000;15.32870; 99.60108;      75.00000; 0.000000e+000;75.00000; 2.018439e-002;0.67884;4
605.09956;246.75000;15.44860; 99.61710;      75.00000; 0.000000e+000;75.00000;      -0.12878;0.67529;4
607.34282;247.50000;15.55935; 99.57042;      75.00000; 0.000000e+000;75.00000;      -0.63404;0.67175;4
609.58466;248.25000;15.68713; 99.55387;      75.00000; 0.000000e+000;75.00000;       0.38324;0.66822;4
611.86275;249.00000;15.80757; 99.55906;      75.00000; 0.000000e+000;75.00000;       0.26269;0.66462;4
614.10790;249.75000;15.93603; 99.60492;      75.00000; 0.000000e+000;75.00000;      -0.10400;0.66107;4
616.34762;250.50000;16.06036; 99.57598;      75.00000; 0.000000e+000;75.00000;       0.10095;0.65753;4
618.58140;251.25000;16.18704; 99.61119;      75.00000; 0.000000e+000;75.00000;      -0.18839;0.65400;4
620.84255;252.00000;16.31356; 99.58871;      75.00000; 0.000000e+000;75.00000;-5.235614e-002;0.65043;4
623.10347;252.75000;16.43618; 99.64450;      75.00000; 0.000000e+000;75.00000;      -0.45610;0.64685;4
625.35972;253.50000;16.57143; 99.57382;      75.00000; 0.000000e+000;75.00000;      -0.22653;0.64328;4
627.61302;254.25000;16.69703; 99.54358;      75.00000; 0.000000e+000;75.00000;       0.18819;0.63971;4
629.85530;255.00000;16.83464; 99.64356;      75.00000; 0.000000e+000;75.00000;      -0.22615;0.63616;4
632.10432;255.75000;16.96950; 99.60218;      75.00000; 0.000000e+000;75.00000;       0.74961;0.63260;4
634.36056;256.50000;17.10365; 99.64327;      75.00000; 0.000000e+000;75.00000;      -0.35087;0.62903;4
636.59282;257.25000;17.23558; 99.57407;      75.00000; 0.000000e+000;75.00000;-5.037258e-002;0.62549;4
638.84745;258.00000;17.37135; 99.68909;      75.00000; 0.000000e+000;75.00000;       0.18909;0.62192;4
641.10683;258.75000;17.52007; 99.66929;      75.00000; 0.000000e+000;75.00000;       0.34700;0.61834;4
643.35565;259.50000;17.65961; 99.62465;      75.00000; 0.000000e+000;75.00000;      -0.74039;0.61478;4
645.59475;260.25000;17.80447; 99.72574;      75.00000; 0.000000e+000;75.00000;-3.836373e-002;0.61124;4
647.84218;261.00000;17.95506; 99.69720;      75.00000; 0.000000e+000;75.00000;      -1.23114;0.60769;4
650.10281;261.75000;18.11131; 99.72185;      75.00000; 0.000000e+000;75.00000; 3.194999e-002;0.60411;4
652.35184;262.50000;18.26661; 99.76114;      75.00000; 0.000000e+000;75.00000;       0.61720;0.60056;4
654.59077;263.25000;18.42774; 99.78951;      75.00000; 0.000000e+000;75.00000;       0.23083;0.59702;4
656.85247;264.00000;18.58419; 99.86663;      75.00000; 0.000000e+000;75.00000;-4.224849e-002;0.59345;4
659.09516;264.75000;18.74114; 99.80842;      75.00000; 0.000000e+000;75.00000;      -0.45453;0.58991;4
661.34472;265.50000;18.90044; 99.82412;      75.00000; 0.000000e+000;75.00000; 8.066742e-002;0.58636;4
663.60443;266.25000;19.06968; 99.81501;      75.00000; 0.000000e+000;75.00000;      -0.21401;0.58280;4
665.83986;267.00000;19.23791; 99.88755;      75.00000; 0.000000e+000;75.00000;      -0.46361;0.57928;4
668.09929;267.75000;19.39222; 99.84177;      75.00000; 0.000000e+000;75.00000;-8.293004e-002;0.57573;4
670.35373;268.50000;19.55822; 99.88815;      75.00000; 0.000000e+000;75.00000;      -0.26590;0.57219;4
672.57833;269.25000;19.72782; 99.90344;      75.00000; 0.000000e+000;75.00000;       0.21098;0.56869;4
674.85640;270.00000;19.89791; 99.98122;      75.00000; 0.000000e+000;75.00000;       0.29792;0.56512;4
677.10948;270.75000;20.06115; 99.94161;      75.00000; 0.000000e+000;75.00000;      -0.57129;0.56159;4
679.36385;271.50000;20.23220; 99.98621;      75.00000; 0.000000e+000;75.00000;       0.75921;0.55806;4
681.60876;272.25000;20.39935;100.00514;      75.00000; 0.000000e+000;75.00000;      -0.18778;0.55456;4
683.86533;273.00000;20.58202;100.04085;      75.00000; 0.000000e+000;75.00000; 8.985525e-002;0.55103;4
686.09269;273.75000;20.75065; 99.96052;      75.00000; 0.000000e+000;75.00000;       0.12150;0.54756;4
688.36069;274.50000;20.93201;100.04284;      75.00000; 0.000000e+000;75.00000;-1.889834e-002;0.54403;4
690.60701;275.25000;21.09666;100.06325;      75.00000; 0.000000e+000;75.00000;       0.33150;0.54054;4
692.85115;276.00000;21.27960;100.03786;      75.00000; 0.000000e+000;75.00000;      -0.41223;0.53705;4
695.13587;276.75000;21.46457;100.05724;      75.00000; 0.000000e+000;75.00000;-3.052350e-003;0.53351;4
697.37177;277.50000;21.65342;100.11491;      75.00000; 0.000000e+000;75.00000; 1.431676e-002;0.53005;4
699.61114;278.25000;21.84292;100.17034;      75.00000; 0.000000e+000;75.00000;      -0.23009;0.52659;4