File: ExpDat_60CP60012CoPU10GPM-1C.txt
#EXPORTTYPE:DATA ALL
#FILE:60CP60012CoPU10GPM-1C.ngb-ss4
#FORMAT:NETZSCH5
#FTYPE:ANSI
#IDENTITY:60CP60012CoPU10GPM-1C
#DECIMAL:POINT
#SEPARATOR:SEMICOLON
#MTYPE:DTA
#INSTRUMENT:NETZSCH STA 2500
#PROJECT:HÉCTOR ROMERO
#DATE/TIME:12.02.2020 11:51
#CORR. FILE:
#TEMPCAL:cal prueba.ngb-ts4
#SENSITIVITY:prueba cal sensibilidad.ngb-es4
#LABORATORY:ESIQIE
#OPERATOR:wendynoemi
#REMARK:
#SAMPLE:60CP60012CoPU10GPM-1C
#SAMPLE MASS /mg:4.998
#MATERIAL:ALUMINA
#REFERENCE:Crisol+Alumina
#REFERENCE MASS /mg:5.189
#TYPE OF CRUCIBLE:Al2O3 pan for STA2500
#SAMPLE CRUCIBLE MASS /mg:38.400
#REFERENCE CRUCIBLE MASS /mg:37.662
#TG RANGE /mg:500
#TAU-R:---
#CORR. CODE:000
#EXO:-1
#RANGE:20°C....700°C/-10.0....10.0K/min
#SEGMENT:S1-4/4
#SEG. 1:20°C/10.0(K/min)/150°C
#SEG. 2:150°C/00:30/150°C
#SEG. 3:150°C/10.0(K/min)/30°C
#SEG. 4:30°C/10.0(K/min)/700°C

##Temp./°C;Time/min;DTA/(mW/mg);Mass/%;Gas Flow(purge1)/(ml/min);Gas Flow(purge2)/(ml/min);Gas Flow(protective)/(ml/min);DTG/(%/min);Sensit./(uV/mW);Segment
 23.87500;  0.00000; 5.91569;100.00000; 0.000000e+000;      75.00000;75.00000;      -0.58618;0.92539;1
 24.49600;  0.50000; 6.01043; 99.82873; 0.000000e+000;      75.00000;75.00000;      -0.65288;0.92609;1
 27.44500;  1.00000; 6.08363; 99.66226; 0.000000e+000;      75.00000;75.00000;-3.191241e-002;0.92940;1
 32.01100;  1.50000; 6.07017; 99.62545; 0.000000e+000;      75.00000;75.00000;       0.37344;0.93445;1
 37.33400;  2.00000; 6.06016; 99.72677; 0.000000e+000;      75.00000;75.00000;       0.45403;0.94023;1
 42.87500;  2.50000; 6.08138; 99.78103; 0.000000e+000;      75.00000;75.00000;       0.15527;0.94611;1
 48.33900;  3.00000; 6.12139; 99.77455; 0.000000e+000;      75.00000;75.00000;       0.20211;0.95177;1
 53.66500;  3.50000; 6.16763; 99.87811; 0.000000e+000;      75.00000;75.00000;       0.69585;0.95716;1
 58.84000;  4.00000; 6.21692; 99.95710; 0.000000e+000;      75.00000;75.00000;      -0.13641;0.96226;1
 63.96400;  4.50000; 6.26210;100.02369; 0.000000e+000;      75.00000;75.00000;      -1.04668;0.96719;1
 69.00100;  5.00000; 6.30535;100.14894; 0.000000e+000;      75.00000;75.00000;      -0.25220;0.97191;1
 72.51300;  5.50000; 6.38239;100.23105; 0.000000e+000;      75.00000;75.00000;      -0.14508;0.97513;1
 81.32900;  6.00000; 6.31155;100.27931; 0.000000e+000;      75.00000;75.00000;      -1.39893;0.98293;1
 84.42800;  6.50000; 6.46017;100.37671; 0.000000e+000;      75.00000;75.00000;       0.18367;0.98558;1
 88.55400;  7.00000; 6.50217;100.40232; 0.000000e+000;      75.00000;75.00000;      -0.79534;0.98902;1
 93.45500;  7.50000; 6.51747;100.44714; 0.000000e+000;      75.00000;75.00000;      -0.28170;0.99300;1
 98.66100;  8.00000; 6.53578;100.44658; 0.000000e+000;      75.00000;75.00000;      -0.25785;0.99709;1
103.90100;  8.50000; 6.56495;100.57119; 0.000000e+000;      75.00000;75.00000;      -0.12478;1.00105;1
109.06500;  9.00000; 6.60481;100.58519; 0.000000e+000;      75.00000;75.00000;       0.10297;1.00481;1
114.15100;  9.50000; 6.64403;100.63121; 0.000000e+000;      75.00000;75.00000;      -0.67137;1.00837;1
119.17500; 10.00000; 6.67998;100.65626; 0.000000e+000;      75.00000;75.00000;       0.52321;1.01174;1
124.19000; 10.50000; 6.71592;100.70964; 0.000000e+000;      75.00000;75.00000;      -0.92313;1.01496;1
129.20000; 11.00000; 6.75201;100.73149; 0.000000e+000;      75.00000;75.00000;-4.628159e-002;1.01803;1
134.23900; 11.50000; 6.78770;100.83185; 0.000000e+000;      75.00000;75.00000;-4.512837e-002;1.02098;1
139.24300; 12.00000; 6.82056;100.87027; 0.000000e+000;      75.00000;75.00000;      -0.40730;1.02376;1
144.26601; 12.50000; 6.85075;100.82273; 0.000000e+000;      75.00000;75.00000;       0.40046;1.02640;1
149.28968; 13.00000; 6.88019;100.87528; 0.000000e+000;      75.00000;75.00000;      -0.81471;1.02889;2
152.27325; 13.50000; 7.00810;100.90755; 0.000000e+000;      75.00000;75.00000; 2.698110e-002;1.03030;2
152.43145; 14.00000; 7.14661;100.94008; 0.000000e+000;      75.00000;75.00000;-7.944780e-003;1.03038;2
151.73931; 14.50000; 7.20165;100.94573; 0.000000e+000;      75.00000;75.00000; 1.611248e-002;1.03005;2
151.01155; 15.00000; 7.20027;101.06316; 0.000000e+000;      75.00000;75.00000; 7.609693e-002;1.02971;2
150.47325; 15.50000; 7.16939;101.10733; 0.000000e+000;      75.00000;75.00000;       0.21212;1.02946;2
150.18905; 16.00000; 7.13460;101.10383; 0.000000e+000;      75.00000;75.00000;-1.269252e-002;1.02932;2
150.06360; 16.50000; 7.10284;101.17458; 0.000000e+000;      75.00000;75.00000;-9.514179e-003;1.02926;2
150.02211; 17.00000; 7.07898;101.19707; 0.000000e+000;      75.00000;75.00000;       0.20304;1.02924;2
150.01166; 17.50000; 7.06331;101.27746; 0.000000e+000;      75.00000;75.00000;       0.18849;1.02924;2
150.02945; 18.00000; 7.04807;101.33891; 0.000000e+000;      75.00000;75.00000;       0.21539;1.02925;2
150.03892; 18.50000; 7.03891;101.35064; 0.000000e+000;      75.00000;75.00000; 6.550532e-002;1.02925;2
150.06656; 19.00000; 7.02788;101.42557; 0.000000e+000;      75.00000;75.00000;-7.210880e-003;1.02927;2
150.04910; 19.50000; 7.02177;101.40098; 0.000000e+000;      75.00000;75.00000; 7.243665e-002;1.02926;2
150.06313; 20.00000; 7.01681;101.45653; 0.000000e+000;      75.00000;75.00000;-9.660208e-002;1.02926;2
150.05632; 20.50000; 7.01334;101.49278; 0.000000e+000;      75.00000;75.00000; 3.935952e-002;1.02926;2
150.04949; 21.00000; 7.00896;101.57694; 0.000000e+000;      75.00000;75.00000;-7.240547e-002;1.02926;2
150.05272; 21.50000; 7.00366;101.63573; 0.000000e+000;      75.00000;75.00000;       0.19119;1.02926;2
150.02650; 22.00000; 6.99955;101.65261; 0.000000e+000;      75.00000;75.00000; 9.365640e-002;1.02925;2
149.99708; 22.50000; 6.99966;101.67285; 0.000000e+000;      75.00000;75.00000;       0.18950;1.02923;2
150.05163; 23.00000; 6.99518;101.79285; 0.000000e+000;      75.00000;75.00000;       0.11036;1.02926;2
150.04411; 23.50000; 6.99381;101.76322; 0.000000e+000;      75.00000;75.00000;       0.25862;1.02925;2
150.03822; 24.00000; 6.99258;101.84053; 0.000000e+000;      75.00000;75.00000; 2.256848e-002;1.02925;2
150.02797; 24.50000; 6.99006;101.90412; 0.000000e+000;      75.00000;75.00000; 4.924641e-002;1.02925;2
150.03090; 25.00000; 6.98749;101.91517; 0.000000e+000;      75.00000;75.00000;       0.11168;1.02925;2
150.03237; 25.50000; 6.98695;101.98426; 0.000000e+000;      75.00000;75.00000;-5.229821e-002;1.02925;2
150.04333; 26.00000; 6.98634;102.10306; 0.000000e+000;      75.00000;75.00000; 8.993523e-002;1.02925;2
150.03951; 26.50000; 6.98583;102.11985; 0.000000e+000;      75.00000;75.00000;       0.28403;1.02925;2
150.02012; 27.00000; 6.98450;102.15585; 0.000000e+000;      75.00000;75.00000; 2.718879e-002;1.02924;2
150.02627; 27.50000; 6.98202;102.13724; 0.000000e+000;      75.00000;75.00000; 4.185107e-002;1.02925;2
150.01403; 28.00000; 6.98164;102.20433; 0.000000e+000;      75.00000;75.00000;       0.20179;1.02924;2
150.01950; 28.50000; 6.98197;102.29115; 0.000000e+000;      75.00000;75.00000;-5.808594e-002;1.02924;2
150.01441; 29.00000; 6.98105;102.33361; 0.000000e+000;      75.00000;75.00000; 7.964017e-002;1.02924;2
150.01089; 29.50000; 6.98064;102.39453; 0.000000e+000;      75.00000;75.00000; 8.716464e-002;1.02924;2
150.01896; 30.00000; 6.97983;102.39821; 0.000000e+000;      75.00000;75.00000; 2.949883e-002;1.02924;2
150.01514; 30.50000; 6.98081;102.45024; 0.000000e+000;      75.00000;75.00000; 4.233036e-002;1.02924;2
150.02199; 31.00000; 6.98014;102.44638; 0.000000e+000;      75.00000;75.00000;-5.526969e-002;1.02924;2
150.01791; 31.50000; 6.97895;102.57553; 0.000000e+000;      75.00000;75.00000;       0.22872;1.02924;2
150.02194; 32.00000; 6.98018;102.62330; 0.000000e+000;      75.00000;75.00000;      -0.15006;1.02924;2
150.00805; 32.50000; 6.97943;102.61700; 0.000000e+000;      75.00000;75.00000; 2.590429e-002;1.02924;2
150.03148; 33.00000; 6.97910;102.65718; 0.000000e+000;      75.00000;75.00000; 5.200438e-002;1.02925;2
150.02396; 33.50000; 6.97895;102.68059; 0.000000e+000;      75.00000;75.00000;       0.14717;1.02925;2
150.01417; 34.00000; 6.97751;102.82899; 0.000000e+000;      75.00000;75.00000;       0.21759;1.02924;2
150.01761; 34.50000; 6.97929;102.86294; 0.000000e+000;      75.00000;75.00000;-1.574775e-003;1.02924;2
150.02067; 35.00000; 6.97881;102.86641; 0.000000e+000;      75.00000;75.00000; 2.742965e-002;1.02924;2
150.01810; 35.50000; 6.97927;102.94310; 0.000000e+000;      75.00000;75.00000;       0.14507;1.02924;2
150.01454; 36.00000; 6.97781;103.00980; 0.000000e+000;      75.00000;75.00000;       0.10932;1.02924;2
150.00239; 36.50000; 6.97795;103.02505; 0.000000e+000;      75.00000;75.00000;       0.11257;1.02923;2
150.01270; 37.00000; 6.97797;103.03980; 0.000000e+000;      75.00000;75.00000;       0.34887;1.02924;2
150.00072; 37.50000; 6.97932;103.12522; 0.000000e+000;      75.00000;75.00000;-7.540718e-002;1.02923;2
149.99790; 38.00000; 6.97940;103.13648; 0.000000e+000;      75.00000;75.00000;-5.474577e-002;1.02923;2
149.99701; 38.50000; 6.98008;103.26400; 0.000000e+000;      75.00000;75.00000;       0.15099;1.02923;2
149.99809; 39.00000; 6.97753;103.22236; 0.000000e+000;      75.00000;75.00000;       0.13897;1.02923;2
150.01438; 39.50000; 6.97886;103.36037; 0.000000e+000;      75.00000;75.00000;       0.19907;1.02924;2
150.00888; 40.00000; 6.97894;103.40613; 0.000000e+000;      75.00000;75.00000; 1.767493e-002;1.02924;2
150.01695; 40.50000; 6.97700;103.46813; 0.000000e+000;      75.00000;75.00000; 3.091515e-002;1.02924;2
150.00621; 41.00000; 6.97903;103.53295; 0.000000e+000;      75.00000;75.00000; 6.222572e-002;1.02924;2
149.99278; 41.50000; 6.98006;103.59294; 0.000000e+000;      75.00000;75.00000; 4.909871e-004;1.02923;2
149.99515; 42.00000; 6.97860;103.63387; 0.000000e+000;      75.00000;75.00000; 1.423786e-002;1.02923;2
150.02797; 42.50000; 6.97880;103.66285; 0.000000e+000;      75.00000;75.00000;-3.636080e-003;1.02925;2
150.02300; 43.00000; 6.97966;103.63575; 0.000000e+000;      75.00000;75.00000;      -0.18574;1.02924;3
148.16615; 43.50000; 7.05978;103.69304; 0.000000e+000;      75.00000;75.00000; 8.733720e-002;1.02835;3
143.38780; 44.00000; 7.16025;103.70975; 0.000000e+000;      75.00000;75.00000;      -1.07980;1.02595;3
137.76742; 44.50000; 7.17142;103.72616; 0.000000e+000;      75.00000;75.00000;       1.09874;1.02296;3
132.09770; 45.00000; 7.12783;103.81883; 0.000000e+000;      75.00000;75.00000;       0.17456;1.01975;3
126.59389; 45.50000; 7.06122;103.83832; 0.000000e+000;      75.00000;75.00000;      -0.39905;1.01645;3
121.36298; 46.00000; 6.98545;103.87046; 0.000000e+000;      75.00000;75.00000;      -0.42690;1.01316;3
116.44689; 46.50000; 6.91369;103.96148; 0.000000e+000;      75.00000;75.00000;      -0.59704;1.00992;3
111.86848; 47.00000; 6.84088;104.01097; 0.000000e+000;      75.00000;75.00000;-3.520465e-002;1.00679;3
107.62845; 47.50000; 6.77653;104.02284; 0.000000e+000;      75.00000;75.00000;      -0.12080;1.00378;3
103.65614; 48.00000; 6.71703;104.06061; 0.000000e+000;      75.00000;75.00000;       0.28024;1.00087;3
 99.92684; 48.50000; 6.66673;104.15983; 0.000000e+000;      75.00000;75.00000;       0.44858;0.99806;3
 96.45580; 49.00000; 6.62386;104.19841; 0.000000e+000;      75.00000;75.00000;      -0.78457;0.99537;3
 93.14600; 49.50000; 6.58325;104.20196;-4.541713e-315;      75.00000;75.00000;      -0.51611;0.99275;3
 90.04639; 50.00000; 6.54911;104.23591;-1.797203e-286;      75.00000;75.00000;      -0.69028;0.99025;3
 87.09634; 50.50000; 6.51392;104.23388;-7.111716e-258;      75.00000;75.00000; 2.021644e-002;0.98782;3
 84.29936; 51.00000; 6.48452;104.32580;-2.814180e-229;      75.00000;75.00000;       0.56934;0.98547;3
 81.65827; 51.50000; 6.45580;104.40901;-1.113600e-200;      75.00000;75.00000;       1.05171;0.98321;3
 79.12809; 52.00000; 6.43212;104.36578;-4.406630e-172;      75.00000;75.00000;      -0.63928;0.98102;3
 76.73771; 52.50000; 6.40728;104.41828;-1.743749e-143;      75.00000;75.00000; 6.466341e-002;0.97892;3
 74.45607; 53.00000; 6.38545;104.51632;-6.900194e-115;      75.00000;75.00000;       0.73254;0.97688;3
 72.26477; 53.50000; 6.36503;104.50958;-2.730478e-086;      75.00000;75.00000;      -0.29926;0.97490;3
 70.18825; 54.00000; 6.34287;104.54140;-1.080478e-057;      75.00000;75.00000;-6.042622e-002;0.97301;3
 68.18736; 54.50000; 6.32406;104.55399;-4.275564e-029;      75.00000;75.00000; 4.384319e-002;0.97116;3
 66.26385; 55.00000; 6.30807;104.60532;      -0.90926;      75.90926;75.00000;-2.948632e-002;0.96936;3
 64.43099; 55.50000; 6.23195;104.67293;      75.00000;-4.849700e-028;75.00000;      -1.95627;0.96763;4
 62.68998; 56.00000; 6.24918;104.79729;      75.00000;-1.225568e-056;75.00000;       0.52830;0.96598;4
 61.00149; 56.50000; 6.25710;104.81796;      75.00000;-3.097135e-085;75.00000;       0.90904;0.96436;4
 59.40087; 57.00000; 6.24863;104.83852;      75.00000;-7.826773e-114;75.00000;       0.98565;0.96281;4
 57.87536; 57.50000; 6.23783;104.84631;      75.00000;-1.977905e-142;75.00000;       1.56024;0.96132;4
 56.42554; 58.00000; 6.22562;104.85561;      75.00000;-4.998365e-171;75.00000; 9.226138e-002;0.95990;4
 55.08246; 58.50000; 6.21352;104.89051;      75.00000;-1.263137e-199;75.00000;       1.36035;0.95857;4
 58.33408; 59.00000; 6.15167;104.99192;      75.00000;-3.192076e-228;75.00000;       0.62723;0.96177;4
 65.82638; 59.50000; 6.07937;104.95856;      75.00000;-8.066699e-257;75.00000;      -0.63934;0.96895;4
 74.12976; 60.00000; 6.08957;105.00560;      75.00000;-2.038536e-285;75.00000;       0.33899;0.97659;4
 81.70871; 60.50000; 6.15879;105.10873;      75.00000;-5.151588e-314;75.00000;      -0.23868;0.98326;4
 88.27630; 61.00000; 6.26574;105.09476;      75.00000; 0.000000e+000;75.00000;      -0.18712;0.98879;4
 94.08365; 61.50000; 6.36454;105.08891;      75.00000; 0.000000e+000;75.00000;       1.53022;0.99350;4
 99.33280; 62.00000; 6.44880;105.11475;      75.00000; 0.000000e+000;75.00000;      -1.04411;0.99760;4
104.34356; 62.50000; 6.51563;105.11412;      75.00000; 0.000000e+000;75.00000;       0.27933;1.00138;4
109.25454; 63.00000; 6.57098;105.25529;      75.00000; 0.000000e+000;75.00000;      -0.51018;1.00494;4
114.15754; 63.50000; 6.61858;105.18542;      75.00000; 0.000000e+000;75.00000;       0.29124;1.00837;4
119.10490; 64.00000; 6.65905;105.23164;      75.00000; 0.000000e+000;75.00000;      -0.23414;1.01169;4
124.06963; 64.50000; 6.69353;105.20863;      75.00000; 0.000000e+000;75.00000;       0.24666;1.01488;4
129.08086; 65.00000; 6.73309;105.24917;      75.00000; 0.000000e+000;75.00000;       0.38232;1.01796;4
134.11794; 65.50000; 6.76412;105.32971;      75.00000; 0.000000e+000;75.00000;-3.410299e-002;1.02091;4
139.14854; 66.00000; 6.79800;105.30137;      75.00000; 0.000000e+000;75.00000;      -0.30543;1.02371;4
144.19499; 66.50000; 6.83212;105.33409;      75.00000; 0.000000e+000;75.00000;      -0.23391;1.02637;4
149.23120; 67.00000; 6.86543;105.29040;      75.00000; 0.000000e+000;75.00000;       0.51221;1.02887;4
154.23979; 67.50000; 6.90010;105.36313;      75.00000; 0.000000e+000;75.00000;       0.81991;1.03120;4
159.25210; 68.00000; 6.93066;105.36368;      75.00000; 0.000000e+000;75.00000;-7.130605e-003;1.03339;4
164.26168; 68.50000; 6.95625;105.37345;      75.00000; 0.000000e+000;75.00000;      -0.78141;1.03542;4
169.24780; 69.00000; 6.98248;105.38146;      75.00000; 0.000000e+000;75.00000;       1.46451;1.03729;4
174.24454; 69.50000; 7.00680;105.44801;      75.00000; 0.000000e+000;75.00000; 6.376241e-002;1.03901;4
179.28343; 70.00000; 7.02901;105.46615;      75.00000; 0.000000e+000;75.00000;       0.17012;1.04059;4
184.28677; 70.50000; 7.04848;105.48941;      75.00000; 0.000000e+000;75.00000;       0.87651;1.04200;4
189.29748; 71.00000; 7.06253;105.53671;      75.00000; 0.000000e+000;75.00000;      -0.16541;1.04326;4
194.31653; 71.50000; 7.06973;105.42628;      75.00000; 0.000000e+000;75.00000;      -0.45787;1.04436;4
199.32118; 72.00000; 7.06701;105.49889;      75.00000; 0.000000e+000;75.00000; 7.997201e-002;1.04530;4
204.32925; 72.50000; 7.05389;105.50469;      75.00000; 0.000000e+000;75.00000;       0.19601;1.04608;4
209.32895; 73.00000; 7.03459;105.45713;      75.00000; 0.000000e+000;75.00000;      -0.43417;1.04671;4
214.32618; 73.50000; 7.01022;105.44935;      75.00000; 0.000000e+000;75.00000;      -0.67204;1.04717;4
219.33665; 74.00000; 6.98672;105.41861;      75.00000; 0.000000e+000;75.00000;      -0.33027;1.04748;4
224.33960; 74.50000; 6.98887;105.36698;      75.00000; 0.000000e+000;75.00000;       0.32452;1.04763;4
229.33171; 75.00000; 7.03489;105.33239;      75.00000; 0.000000e+000;75.00000;       1.54008;1.04762;4
234.27990; 75.50000; 7.11874;105.29254;      75.00000; 0.000000e+000;75.00000;      -0.42289;1.04745;4
239.30472; 76.00000; 7.21049;105.31832;      75.00000; 0.000000e+000;75.00000;      -0.73626;1.04712;4
244.32042; 76.50000; 7.29083;105.33963;      75.00000; 0.000000e+000;75.00000;       0.29297;1.04664;4
249.31643; 77.00000; 7.35136;105.38980;      75.00000; 0.000000e+000;75.00000;       1.14212;1.04599;4
254.34088; 77.50000; 7.39607;105.36925;      75.00000; 0.000000e+000;75.00000;      -1.13657;1.04518;4
259.32614; 78.00000; 7.43630;105.34947;      75.00000; 0.000000e+000;75.00000;       0.40347;1.04422;4
264.33474; 78.50000; 7.47245;105.34355;      75.00000; 0.000000e+000;75.00000;      -0.79374;1.04310;4
269.35073; 79.00000; 7.51180;105.34223;      75.00000; 0.000000e+000;75.00000;       0.16196;1.04182;4
274.34598; 79.50000; 7.54830;105.28985;      75.00000; 0.000000e+000;75.00000; 8.153465e-002;1.04038;4
279.35405; 80.00000; 7.57824;105.36686;      75.00000; 0.000000e+000;75.00000;       0.37260;1.03879;4
284.36088; 80.50000; 7.60904;105.36066;      75.00000; 0.000000e+000;75.00000;-5.723179e-002;1.03704;4
289.36243; 81.00000; 7.64436;105.37318;      75.00000; 0.000000e+000;75.00000;       0.98904;1.03514;4
294.37201; 81.50000; 7.67680;105.35953;      75.00000; 0.000000e+000;75.00000;       1.31678;1.03308;4
299.37341; 82.00000; 7.70535;105.38512;      75.00000; 0.000000e+000;75.00000;       0.67622;1.03087;4
304.35139; 82.50000; 7.72892;105.41297;      75.00000; 0.000000e+000;75.00000;       0.81714;1.02852;4
309.35644; 83.00000; 7.75022;105.31179;      75.00000; 0.000000e+000;75.00000;       0.86581;1.02601;4
314.37136; 83.50000; 7.76484;105.29242;      75.00000; 0.000000e+000;75.00000;      -0.45455;1.02334;4
319.36023; 84.00000; 7.77286;105.29158;      75.00000; 0.000000e+000;75.00000;       0.30431;1.02053;4
324.37414; 84.50000; 7.76701;105.27999;      75.00000; 0.000000e+000;75.00000;      -1.47142;1.01757;4
329.36900; 85.00000; 7.75104;105.25810;      75.00000; 0.000000e+000;75.00000;      -1.46005;1.01446;4
334.37499; 85.50000; 7.71866;105.15973;      75.00000; 0.000000e+000;75.00000;      -0.32458;1.01121;4
339.36772; 86.00000; 7.67244;105.16104;      75.00000; 0.000000e+000;75.00000;       0.52220;1.00782;4
344.36205; 86.50000; 7.59496;105.07047;      75.00000; 0.000000e+000;75.00000;      -0.42039;1.00429;4
349.37665; 87.00000; 7.48984;105.03168;      75.00000; 0.000000e+000;75.00000;       0.91963;1.00060;4
354.38485; 87.50000; 7.34336;104.96209;      75.00000; 0.000000e+000;75.00000;      -0.17982;0.99678;4
359.38471; 88.00000; 7.15555;104.76806;      75.00000; 0.000000e+000;75.00000;      -1.17471;0.99283;4
364.39324; 88.50000; 6.90943;104.53576;      75.00000; 0.000000e+000;75.00000;      -0.67853;0.98873;4
369.38181; 89.00000; 6.59629;104.31321;      75.00000; 0.000000e+000;75.00000;      -1.00195;0.98452;4
374.39300; 89.50000; 6.20483;104.02139;      75.00000; 0.000000e+000;75.00000;      -1.06571;0.98015;4
379.40055; 90.00000; 5.75179;103.66542;      75.00000; 0.000000e+000;75.00000;      -1.10969;0.97566;4
384.40975; 90.50000; 5.24643;103.26146;      75.00000; 0.000000e+000;75.00000;      -0.88364;0.97103;4
389.40527; 91.00000; 4.73951;102.73985;      75.00000; 0.000000e+000;75.00000;      -1.50743;0.96630;4
394.41979; 91.50000; 4.30139;102.06868;      75.00000; 0.000000e+000;75.00000;      -0.83351;0.96142;4
399.41840; 92.00000; 4.01565;101.39674;      75.00000; 0.000000e+000;75.00000;      -2.16147;0.95643;4
404.42175; 92.50000; 3.94853;100.73145;      75.00000; 0.000000e+000;75.00000;      -1.27731;0.95132;4
409.43081; 93.00000; 4.11707;100.08723;      75.00000; 0.000000e+000;75.00000;      -1.93878;0.94608;4
414.42680; 93.50000; 4.49203; 99.51282;      75.00000; 0.000000e+000;75.00000;      -0.43153;0.94074;4
419.40264; 94.00000; 5.01887; 98.83433;      75.00000; 0.000000e+000;75.00000;      -1.34161;0.93531;4
424.38013; 94.50000; 5.64744; 98.41296;      75.00000; 0.000000e+000;75.00000;       0.58836;0.92977;4
429.35735; 95.00000; 6.32849; 97.97564;      75.00000; 0.000000e+000;75.00000;       0.77279;0.92412;4
434.34443; 95.50000; 7.01202; 97.58774;      75.00000; 0.000000e+000;75.00000;      -1.02306;0.91835;4
439.34889; 96.00000; 7.66840; 97.37615;      75.00000; 0.000000e+000;75.00000;      -0.67905;0.91245;4
444.35522; 96.50000; 8.28451; 97.15731;      75.00000; 0.000000e+000;75.00000;      -1.79700;0.90646;4
449.35379; 97.00000; 8.83666; 96.97664;      75.00000; 0.000000e+000;75.00000;      -0.58158;0.90037;4
454.36544; 97.50000; 9.31266; 96.86697;      75.00000; 0.000000e+000;75.00000;      -0.97453;0.89417;4
459.37332; 98.00000; 9.72376; 96.72498;      75.00000; 0.000000e+000;75.00000;-2.107447e-002;0.88788;4
464.36248; 98.50000;10.06774; 96.68057;      75.00000; 0.000000e+000;75.00000;-3.242963e-002;0.88152;4
469.35925; 99.00000;10.34727; 96.65610;      75.00000; 0.000000e+000;75.00000;      -0.88768;0.87506;4
474.38063; 99.50000;10.56992; 96.61960;      75.00000; 0.000000e+000;75.00000;       0.51751;0.86848;4
479.38217;100.00000;10.76799; 96.64268;      75.00000; 0.000000e+000;75.00000;       0.96332;0.86184;4
484.39717;100.50000;10.93857; 96.62970;      75.00000; 0.000000e+000;75.00000;-2.493278e-002;0.85511;4
489.38230;101.00000;11.08820; 96.61285;      75.00000; 0.000000e+000;75.00000;      -0.41520;0.84833;4
494.40476;101.50000;11.23516; 96.53700;      75.00000; 0.000000e+000;75.00000;       0.32395;0.84143;4
499.39935;102.00000;11.38497; 96.60870;      75.00000; 0.000000e+000;75.00000;      -0.88124;0.83449;4
504.40565;102.50000;11.53886; 96.62131;      75.00000; 0.000000e+000;75.00000;      -0.82325;0.82746;4
509.40426;103.00000;11.68925; 96.60351;      75.00000; 0.000000e+000;75.00000;       0.20147;0.82038;4
514.39049;103.50000;11.84222; 96.60255;      75.00000; 0.000000e+000;75.00000;       0.80714;0.81325;4
519.40099;104.00000;12.00015; 96.56165;      75.00000; 0.000000e+000;75.00000;      -0.11806;0.80602;4
524.41518;104.50000;12.15934; 96.54304;      75.00000; 0.000000e+000;75.00000;      -0.46282;0.79872;4
529.42003;105.00000;12.32518; 96.59691;      75.00000; 0.000000e+000;75.00000;       0.11783;0.79139;4
534.40209;105.50000;12.49801; 96.56891;      75.00000; 0.000000e+000;75.00000;      -0.50309;0.78403;4
539.41580;106.00000;12.68223; 96.53255;      75.00000; 0.000000e+000;75.00000;      -0.12087;0.77657;4
544.42742;106.50000;12.86738; 96.56872;      75.00000; 0.000000e+000;75.00000;      -0.98054;0.76906;4
549.41461;107.00000;13.06183; 96.52172;      75.00000; 0.000000e+000;75.00000;       1.90865;0.76155;4
554.42844;107.50000;13.25782; 96.57813;      75.00000; 0.000000e+000;75.00000;       0.33508;0.75395;4
559.44852;108.00000;13.45588; 96.52937;      75.00000; 0.000000e+000;75.00000;      -0.58642;0.74630;4
564.45550;108.50000;13.66514; 96.55921;      75.00000; 0.000000e+000;75.00000;      -0.25393;0.73863;4
569.45283;109.00000;13.87833; 96.54978;      75.00000; 0.000000e+000;75.00000;      -0.55642;0.73094;4
574.44224;109.50000;14.08906; 96.55005;      75.00000; 0.000000e+000;75.00000;       0.75529;0.72323;4
579.46302;110.00000;14.31244; 96.50267;      75.00000; 0.000000e+000;75.00000;       0.47934;0.71544;4
584.47844;110.50000;14.54275; 96.53929;      75.00000; 0.000000e+000;75.00000; 6.599282e-002;0.70763;4
589.48590;111.00000;14.78503; 96.51449;      75.00000; 0.000000e+000;75.00000;       1.17817;0.69981;4
594.49921;111.50000;15.03722; 96.47471;      75.00000; 0.000000e+000;75.00000;      -1.19277;0.69195;4
599.52649;112.00000;15.29753; 96.45746;      75.00000; 0.000000e+000;75.00000;      -0.55900;0.68406;4
604.54530;112.50000;15.57356; 96.40013;      75.00000; 0.000000e+000;75.00000;       0.61826;0.67616;4
609.52383;113.00000;15.84419; 96.38023;      75.00000; 0.000000e+000;75.00000;       0.24128;0.66831;4
614.50344;113.50000;16.10909; 96.40334;      75.00000; 0.000000e+000;75.00000;       1.09602;0.66045;4
619.48595;114.00000;16.37875; 96.34901;      75.00000; 0.000000e+000;75.00000; 4.026234e-002;0.65257;4
624.49637;114.50000;16.65998; 96.35999;      75.00000; 0.000000e+000;75.00000;      -0.36591;0.64464;4
629.50558;115.00000;16.94586; 96.31800;      75.00000; 0.000000e+000;75.00000; 3.678322e-002;0.63671;4
634.49354;115.50000;17.23244; 96.39363;      75.00000; 0.000000e+000;75.00000;-2.473433e-003;0.62881;4
639.49632;116.00000;17.53495; 96.37664;      75.00000; 0.000000e+000;75.00000;      -0.17239;0.62089;4
644.48311;116.50000;17.83994; 96.37687;      75.00000; 0.000000e+000;75.00000;      -0.20177;0.61300;4
649.49099;117.00000;18.15968; 96.33266;      75.00000; 0.000000e+000;75.00000;      -0.60746;0.60508;4
654.47894;117.50000;18.49417; 96.47717;      75.00000; 0.000000e+000;75.00000;      -0.30054;0.59720;4
659.48111;118.00000;18.84140; 96.36496;      75.00000; 0.000000e+000;75.00000;      -0.14515;0.58930;4
664.47992;118.50000;19.20069; 96.46637;      75.00000; 0.000000e+000;75.00000;       0.25168;0.58142;4
669.50040;119.00000;19.56821; 96.41896;      75.00000; 0.000000e+000;75.00000;      -1.39889;0.57353;4
674.47686;119.50000;19.94131; 96.45608;      75.00000; 0.000000e+000;75.00000;      -0.80125;0.56572;4
679.48727;120.00000;20.33848; 96.50181;      75.00000; 0.000000e+000;75.00000;      -1.24122;0.55787;4
684.47926;120.50000;20.72460; 96.51200;      75.00000; 0.000000e+000;75.00000;       1.34580;0.55008;4
689.50300;121.00000;21.12305; 96.53324;      75.00000; 0.000000e+000;75.00000;      -0.58982;0.54225;4
694.50332;121.50000;21.54007; 96.58690;      75.00000; 0.000000e+000;75.00000;       1.01905;0.53449;4
699.47501;122.00000;21.96154; 96.62528;      75.00000; 0.000000e+000;75.00000;      -1.99429;0.52680;4