File: Example Data/ExpDat_60CP60012CoPU5GPM-1C.txt
#EXPORTTYPE:DATA ALL
#FILE:60CP60012CoPU5GPM-1C.ngb-ss4
#FORMAT:NETZSCH5
#FTYPE:ANSI
#IDENTITY:60CP60012CoPU5GPM-1C
#DECIMAL:POINT
#SEPARATOR:SEMICOLON
#MTYPE:DTA
#INSTRUMENT:NETZSCH STA 2500
#PROJECT:HÉCTOR ROMERO
#DATE/TIME:14.01.2020 10:00
#CORR. FILE:
#TEMPCAL:cal prueba.ngb-ts4
#SENSITIVITY:prueba cal sensibilidad.ngb-es4
#LABORATORY:ESIQIE
#OPERATOR:wendynoemi
#REMARK:
#SAMPLE:60CP60012CoPU5GPM-1C
#SAMPLE MASS /mg:4.980
#MATERIAL:ALUMINA
#REFERENCE:Crisol+Alumina
#REFERENCE MASS /mg:14.783
#TYPE OF CRUCIBLE:Al2O3 pan for STA2500
#SAMPLE CRUCIBLE MASS /mg:38.223
#REFERENCE CRUCIBLE MASS /mg:43.950
#TG RANGE /mg:500
#TAU-R:---
#CORR. CODE:000
#EXO:-1
#RANGE:20°C....700°C/-10.0....10.0K/min
#SEGMENT:S1-4/4
#SEG. 1:20°C/10.0(K/min)/150°C
#SEG. 2:150°C/00:30/150°C
#SEG. 3:150°C/10.0(K/min)/30°C
#SEG. 4:30°C/5.0(K/min)/700°C

##Temp./°C;Time/min;DTA/(mW/mg);Mass/%;Gas Flow(purge1)/(ml/min);Gas Flow(purge2)/(ml/min);Gas Flow(protective)/(ml/min);DTG/(%/min);Sensit./(uV/mW);Segment
 20.55400;  0.00000; 5.90922;100.00000; 0.000000e+000;      75.00000;75.00000;       1.43293;0.92161;1
 22.09600;  0.50000; 6.02488; 99.82731; 0.000000e+000;      75.00000;75.00000;      -0.61208;0.92337;1
 26.25000;  1.00000; 6.16658; 99.32843; 0.000000e+000;      75.00000;75.00000;      -0.93975;0.92806;1
 31.61400;  1.50000; 6.16926; 99.25703; 0.000000e+000;      75.00000;75.00000;      -1.29012;0.93402;1
 37.38800;  2.00000; 6.18384; 99.26281; 0.000000e+000;      75.00000;75.00000;       0.10589;0.94029;1
 43.05900;  2.50000; 6.20023; 99.32819; 0.000000e+000;      75.00000;75.00000;       0.45070;0.94630;1
 48.53500;  3.00000; 6.24859; 99.41944; 0.000000e+000;      75.00000;75.00000;      -0.29563;0.95197;1
 53.81500;  3.50000; 6.29042; 99.49108; 0.000000e+000;      75.00000;75.00000;      -0.58667;0.95731;1
 58.94400;  4.00000; 6.34062; 99.55092; 0.000000e+000;      75.00000;75.00000;       0.38443;0.96236;1
 64.01100;  4.50000; 6.39231; 99.54394; 0.000000e+000;      75.00000;75.00000;       0.46662;0.96724;1
 69.02100;  5.00000; 6.44529; 99.66426; 0.000000e+000;      75.00000;75.00000;      -0.53985;0.97193;1
 74.01400;  5.50000; 6.49682; 99.68225; 0.000000e+000;      75.00000;75.00000;       1.76317;0.97648;1
 79.00600;  6.00000; 6.54308; 99.68225; 0.000000e+000;      75.00000;75.00000;       0.44351;0.98091;1
 84.01300;  6.50000; 6.58706; 99.76080; 0.000000e+000;      75.00000;75.00000;       0.30638;0.98523;1
 89.06300;  7.00000; 6.63067; 99.77020; 0.000000e+000;      75.00000;75.00000;       0.18829;0.98944;1
 94.11600;  7.50000; 6.67542; 99.77510; 0.000000e+000;      75.00000;75.00000;      -0.24346;0.99353;1
 99.17300;  8.00000; 6.71378; 99.86217; 0.000000e+000;      75.00000;75.00000;       1.64829;0.99748;1
104.21600;  8.50000; 6.75820; 99.88940; 0.000000e+000;      75.00000;75.00000;       0.42723;1.00128;1
109.20900;  9.00000; 6.79860; 99.91486; 0.000000e+000;      75.00000;75.00000;       0.59899;1.00491;1
114.17600;  9.50000; 6.83687; 99.94554; 0.000000e+000;      75.00000;75.00000;      -1.08148;1.00838;1
119.18000; 10.00000; 6.87718; 99.84964; 0.000000e+000;      75.00000;75.00000;      -0.17145;1.01174;1
124.19200; 10.50000; 6.92585; 99.97253; 0.000000e+000;      75.00000;75.00000;      -1.41005;1.01496;1
129.20700; 11.00000; 6.96570; 99.99944; 0.000000e+000;      75.00000;75.00000;      -1.01930;1.01804;1
134.24001; 11.50000; 7.00459; 99.96169; 0.000000e+000;      75.00000;75.00000;      -1.38259;1.02098;1
139.27000; 12.00000; 7.04354; 99.90578; 0.000000e+000;      75.00000;75.00000;      -0.36711;1.02378;1
144.30400; 12.50000; 7.07777;100.08586; 0.000000e+000;      75.00000;75.00000;       1.68859;1.02642;1
149.31927; 13.00000; 7.12521;100.13753; 0.000000e+000;      75.00000;75.00000;      -0.37493;1.02891;2
152.27724; 13.50000; 7.24311;100.09154; 0.000000e+000;      75.00000;75.00000;-3.147971e-002;1.03030;2
152.43955; 14.00000; 7.36923;100.07033; 0.000000e+000;      75.00000;75.00000;       0.10049;1.03038;2
151.75778; 14.50000; 7.41821;100.15383; 0.000000e+000;      75.00000;75.00000; 1.722100e-004;1.03006;2
151.01480; 15.00000; 7.41294;100.16786; 0.000000e+000;      75.00000;75.00000;-7.487466e-002;1.02971;2
150.47985; 15.50000; 7.38226;100.18046; 0.000000e+000;      75.00000;75.00000; 6.430121e-002;1.02946;2
150.19769; 16.00000; 7.34497;100.21014; 0.000000e+000;      75.00000;75.00000;       0.16492;1.02933;2
150.05352; 16.50000; 7.31385;100.30871; 0.000000e+000;      75.00000;75.00000;       0.26759;1.02926;2
150.00655; 17.00000; 7.29009;100.33034; 0.000000e+000;      75.00000;75.00000; 2.176352e-002;1.02924;2
150.00894; 17.50000; 7.27209;100.35874; 0.000000e+000;      75.00000;75.00000; 5.782382e-002;1.02924;2
150.03112; 18.00000; 7.25822;100.38603; 0.000000e+000;      75.00000;75.00000;       0.11623;1.02925;2
150.02087; 18.50000; 7.24628;100.35250; 0.000000e+000;      75.00000;75.00000; 2.269385e-002;1.02924;2
150.05234; 19.00000; 7.23675;100.47123; 0.000000e+000;      75.00000;75.00000; 5.021822e-002;1.02926;2
150.05520; 19.50000; 7.22974;100.44474; 0.000000e+000;      75.00000;75.00000; 1.892133e-002;1.02926;2
150.05729; 20.00000; 7.22403;100.49260; 0.000000e+000;      75.00000;75.00000; 4.921687e-002;1.02926;2
150.06952; 20.50000; 7.21832;100.58870; 0.000000e+000;      75.00000;75.00000;       0.16517;1.02927;2
150.04922; 21.00000; 7.21351;100.58360; 0.000000e+000;      75.00000;75.00000;       0.12852;1.02926;2
150.03731; 21.50000; 7.20898;100.60959; 0.000000e+000;      75.00000;75.00000;       0.15425;1.02925;2
150.04208; 22.00000; 7.20503;100.65642; 0.000000e+000;      75.00000;75.00000; 5.245492e-002;1.02925;2
150.04553; 22.50000; 7.20082;100.78099; 0.000000e+000;      75.00000;75.00000; 5.122303e-002;1.02926;2
150.04249; 23.00000; 7.19715;100.72329; 0.000000e+000;      75.00000;75.00000;       0.17625;1.02925;2
150.03986; 23.50000; 7.19511;100.74502; 0.000000e+000;      75.00000;75.00000;       0.21524;1.02925;2
150.03549; 24.00000; 7.19316;100.72134; 0.000000e+000;      75.00000;75.00000;       0.12098;1.02925;2
150.02229; 24.50000; 7.19102;100.80774; 0.000000e+000;      75.00000;75.00000; 9.008977e-002;1.02924;2
150.03273; 25.00000; 7.18853;100.82211; 0.000000e+000;      75.00000;75.00000;-3.853988e-002;1.02925;2
150.03178; 25.50000; 7.18810;100.84012; 0.000000e+000;      75.00000;75.00000; 8.817190e-002;1.02925;2
150.03177; 26.00000; 7.18541;100.86715; 0.000000e+000;      75.00000;75.00000;       0.14463;1.02925;2
150.03451; 26.50000; 7.18389;100.88992; 0.000000e+000;      75.00000;75.00000;-8.349231e-002;1.02925;2
150.02178; 27.00000; 7.18272;100.96674; 0.000000e+000;      75.00000;75.00000;       0.58453;1.02924;2
150.00596; 27.50000; 7.18046;101.03649; 0.000000e+000;      75.00000;75.00000; 3.084872e-003;1.02924;2
150.02891; 28.00000; 7.18065;101.04583; 0.000000e+000;      75.00000;75.00000; 6.018473e-003;1.02925;2
150.01100; 28.50000; 7.17952;101.11439; 0.000000e+000;      75.00000;75.00000;       0.20572;1.02924;2
150.01661; 29.00000; 7.17848;101.05536; 0.000000e+000;      75.00000;75.00000;       0.18217;1.02924;2
150.02652; 29.50000; 7.17803;101.12444; 0.000000e+000;      75.00000;75.00000;       0.18609;1.02925;2
150.00330; 30.00000; 7.17675;101.17426; 0.000000e+000;      75.00000;75.00000;-5.264283e-002;1.02924;2
150.01907; 30.50000; 7.17581;101.22615; 0.000000e+000;      75.00000;75.00000;       0.22055;1.02924;2
150.01689; 31.00000; 7.17579;101.24700; 0.000000e+000;      75.00000;75.00000; 5.472774e-002;1.02924;2
150.00397; 31.50000; 7.17573;101.22151; 0.000000e+000;      75.00000;75.00000;       0.21765;1.02924;2
150.01130; 32.00000; 7.17542;101.33514; 0.000000e+000;      75.00000;75.00000;       0.11719;1.02924;2
150.00588; 32.50000; 7.17394;101.29247; 0.000000e+000;      75.00000;75.00000; 8.901924e-002;1.02924;2
149.98824; 33.00000; 7.17394;101.11905; 0.000000e+000;      75.00000;75.00000;-5.932717e-002;1.02923;2
150.01147; 33.50000; 7.17259;101.41946; 0.000000e+000;      75.00000;75.00000; 7.011617e-002;1.02924;2
150.02218; 34.00000; 7.17512;101.46999; 0.000000e+000;      75.00000;75.00000;       0.14053;1.02924;2
150.01123; 34.50000; 7.17453;101.45193; 0.000000e+000;      75.00000;75.00000; 5.210620e-002;1.02924;2
150.01156; 35.00000; 7.17433;101.51400; 0.000000e+000;      75.00000;75.00000; 7.237904e-002;1.02924;2
150.00621; 35.50000; 7.17464;101.47116; 0.000000e+000;      75.00000;75.00000; 7.699891e-002;1.02924;2
150.01425; 36.00000; 7.17615;101.53083; 0.000000e+000;      75.00000;75.00000;       0.11670;1.02924;2
150.01052; 36.50000; 7.17499;101.55381; 0.000000e+000;      75.00000;75.00000; 3.886890e-002;1.02924;2
150.01892; 37.00000; 7.17440;101.60706; 0.000000e+000;      75.00000;75.00000; 9.403006e-002;1.02924;2
149.99592; 37.50000; 7.17347;101.70481; 0.000000e+000;      75.00000;75.00000;-2.231048e-002;1.02923;2
149.99071; 38.00000; 7.17414;101.66487; 0.000000e+000;      75.00000;75.00000;       0.10367;1.02923;2
150.01369; 38.50000; 7.17543;101.73482; 0.000000e+000;      75.00000;75.00000;-2.490240e-002;1.02924;2
150.01115; 39.00000; 7.17466;101.68133; 0.000000e+000;      75.00000;75.00000; 6.995397e-002;1.02924;2
150.00032; 39.50000; 7.17539;101.70359; 0.000000e+000;      75.00000;75.00000;       0.12908;1.02923;2
150.00649; 40.00000; 7.17558;101.72491; 0.000000e+000;      75.00000;75.00000; 7.314025e-002;1.02924;2
150.00369; 40.50000; 7.17493;101.77807; 0.000000e+000;      75.00000;75.00000;       0.21364;1.02924;2
149.99471; 41.00000; 7.17661;101.79921; 0.000000e+000;      75.00000;75.00000;-3.088777e-002;1.02923;2
150.00092; 41.50000; 7.17603;101.79055; 0.000000e+000;      75.00000;75.00000; 1.441776e-002;1.02923;2
150.00896; 42.00000; 7.17616;101.87447; 0.000000e+000;      75.00000;75.00000; 5.806595e-002;1.02924;2
150.00183; 42.50000; 7.17590;101.81645; 0.000000e+000;      75.00000;75.00000; 2.219041e-002;1.02923;2
150.01601; 43.00000; 7.17538;101.88104; 0.000000e+000;      75.00000;75.00000;       0.20783;1.02924;3
148.13600; 43.50000; 7.23251;101.86940; 0.000000e+000;      75.00000;75.00000;      -0.65186;1.02833;3
143.33099; 44.00000; 7.23966;101.87253; 0.000000e+000;      75.00000;75.00000;-4.061681e-002;1.02592;3
137.71001; 44.50000; 7.21354;101.90434; 0.000000e+000;      75.00000;75.00000;       0.41269;1.02292;3
132.08299; 45.00000; 7.20213;101.87004; 0.000000e+000;      75.00000;75.00000;       0.76192;1.01974;3
126.60400; 45.50000; 7.12770;101.96353; 0.000000e+000;      75.00000;75.00000;       1.71004;1.01646;3
121.33100; 46.00000; 7.04838;101.94426; 0.000000e+000;      75.00000;75.00000;      -0.20787;1.01314;3
116.29900; 46.50000; 6.96487;102.08337; 0.000000e+000;      75.00000;75.00000;      -0.71482;1.00982;3
111.57300; 47.00000; 6.89280;102.05574; 0.000000e+000;      75.00000;75.00000;       0.81922;1.00658;3
107.16600; 47.50000; 6.82412;102.05173; 0.000000e+000;      75.00000;75.00000;       0.73262;1.00344;3
103.03400; 48.00000; 6.76307;102.04072; 0.000000e+000;      75.00000;75.00000;      -0.16120;1.00040;3
 99.16900; 48.50000; 6.70919;102.12193; 0.000000e+000;      75.00000;75.00000;       0.66532;0.99748;3
 95.55900; 49.00000; 6.66190;102.12072; 0.000000e+000;      75.00000;75.00000;       0.74467;0.99467;3
 92.13300; 49.50000; 6.61721;102.13566; 1.482197e-323;      75.00000;75.00000;      -0.44829;0.99194;3
 88.93700; 50.00000; 6.57856;102.26072; 6.467401e-295;      75.00000;75.00000;      -0.18802;0.98934;3
 85.89800; 50.50000; 6.54586;102.21815; 2.687637e-266;      75.00000;75.00000;       1.07008;0.98682;3
 83.01400; 51.00000; 6.51633;102.28827; 1.114343e-237;      75.00000;75.00000;      -0.42906;0.98437;3
 80.28900; 51.50000; 6.48650;102.26185; 4.610657e-209;      75.00000;75.00000; 6.316051e-002;0.98203;3
 77.67600; 52.00000; 6.45737;102.27888; 1.904057e-180;      75.00000;75.00000;      -0.46907;0.97975;3
 75.20200; 52.50000; 6.43238;102.33847; 7.849427e-152;      75.00000;75.00000;      -0.27885;0.97755;3
 72.83700; 53.00000; 6.40824;102.36643; 3.230699e-123;      75.00000;75.00000;      -0.16279;0.97542;3
 70.58500; 53.50000; 6.38649;102.35518; 1.327726e-094;      75.00000;75.00000;      -0.13205;0.97337;3
 68.42400; 54.00000; 6.36443;102.39550; 5.449057e-066;      75.00000;75.00000;      -0.55024;0.97138;3
 66.36800; 54.50000; 6.34209;102.39004; 2.233454e-037;      75.00000;75.00000;       1.08326;0.96946;3
 64.38852; 55.00000; 6.32243;102.51110;      -4.21950;      79.21950;75.00000;       2.09113;0.96759;3
 62.49597; 55.50000; 6.23442;102.53069;      75.00000;-2.117757e-020;75.00000;       0.49197;0.96579;4
 60.71247; 56.00000; 6.23911;102.65063;      75.00000; 3.371652e-042;75.00000;      -0.20934;0.96408;4
 58.97642; 56.50000; 6.25321;102.66180;      75.00000; 2.690358e-063;75.00000;       0.19113;0.96240;4
 57.31930; 57.00000; 6.25302;102.65878;      75.00000;-4.283282e-085;75.00000;      -0.72579;0.96078;4
 55.75035; 57.50000; 6.23992;102.61913;      75.00000;-3.417779e-106;75.00000;       0.12819;0.95923;4
 54.24775; 58.00000; 6.22761;102.64670;      75.00000; 5.441400e-128;75.00000;       0.69449;0.95774;4
 52.81953; 58.50000; 6.21167;102.69918;      75.00000; 4.341881e-149;75.00000;      -0.29282;0.95631;4
 51.43253; 59.00000; 6.19867;102.62546;      75.00000;-6.912650e-171;75.00000;      -0.37380;0.95492;4
 50.13135; 59.50000; 6.18832;102.76888;      75.00000;-5.515842e-192;75.00000;      -0.49385;0.95360;4
 48.87008; 60.00000; 6.17598;102.77241;      75.00000; 8.781698e-214;75.00000;      -0.41239;0.95231;4
 47.85366; 60.50000; 6.16638;102.77685;      75.00000; 7.007220e-235;75.00000;       0.56707;0.95127;4
 50.42429; 61.00000; 6.15423;102.77035;      75.00000;-1.115610e-256;75.00000;      -0.22478;0.95390;4
 55.53196; 61.50000; 6.14932;102.83449;      75.00000;-8.901838e-278;75.00000;      -0.68687;0.95901;4
 60.86647; 62.00000; 6.18162;102.76382;      75.00000; 1.417250e-299;75.00000;      -0.34899;0.96423;4
 65.42072; 62.50000; 6.24771;102.87379;      75.00000; 1.130916e-320;75.00000;      -0.15924;0.96857;4
 69.06270; 63.00000; 6.32416;102.90115;      75.00000; 0.000000e+000;75.00000;-1.422131e-002;0.97197;4
 72.07404; 63.50000; 6.38993;102.82225;      75.00000; 0.000000e+000;75.00000;       0.90501;0.97473;4
 74.69139; 64.00000; 6.44450;102.86061;      75.00000; 0.000000e+000;75.00000;       0.57348;0.97709;4
 77.13239; 64.50000; 6.48866;102.85955;      75.00000; 0.000000e+000;75.00000;       0.85840;0.97927;4
 79.56175; 65.00000; 6.52370;102.88569;      75.00000; 0.000000e+000;75.00000;      -0.79449;0.98140;4
 81.99771; 65.50000; 6.55461;102.90420;      75.00000; 0.000000e+000;75.00000;      -0.64208;0.98350;4
 84.46575; 66.00000; 6.58365;102.93304;      75.00000; 0.000000e+000;75.00000; 9.002694e-002;0.98561;4
 86.95737; 66.50000; 6.60944;102.95475;      75.00000; 0.000000e+000;75.00000;      -0.21402;0.98770;4
 89.45321; 67.00000; 6.63516;102.95769;      75.00000; 0.000000e+000;75.00000;       0.42285;0.98976;4
 91.97709; 67.50000; 6.66044;102.90960;      75.00000; 0.000000e+000;75.00000;      -0.61450;0.99182;4
 94.48660; 68.00000; 6.68363;102.91887;      75.00000; 0.000000e+000;75.00000;       0.42889;0.99382;4
 97.01899; 68.50000; 6.70601;102.96942;      75.00000; 0.000000e+000;75.00000;-1.604375e-002;0.99581;4
 99.52814; 69.00000; 6.72825;102.97298;      75.00000; 0.000000e+000;75.00000;      -0.23211;0.99775;4
102.00965; 69.50000; 6.75096;102.97419;      75.00000; 0.000000e+000;75.00000;       0.21501;0.99964;4
104.52200; 70.00000; 6.76995;103.04490;      75.00000; 0.000000e+000;75.00000;      -0.80073;1.00151;4
107.03647; 70.50000; 6.78913;103.03105;      75.00000; 0.000000e+000;75.00000;      -0.16009;1.00335;4
109.53069; 71.00000; 6.81054;103.05025;      75.00000; 0.000000e+000;75.00000;       0.30302;1.00514;4
112.03286; 71.50000; 6.82711;103.07145;      75.00000; 0.000000e+000;75.00000;       0.46136;1.00690;4
114.53198; 72.00000; 6.85322;103.05594;      75.00000; 0.000000e+000;75.00000;      -0.17361;1.00863;4
117.01231; 72.50000; 6.88256;103.08220;      75.00000; 0.000000e+000;75.00000;       0.14926;1.01030;4
119.53264; 73.00000; 6.90550;103.10000;      75.00000; 0.000000e+000;75.00000; 2.426406e-002;1.01197;4
122.03837; 73.50000; 6.92682;103.16109;      75.00000; 0.000000e+000;75.00000;       0.99321;1.01359;4
124.53644; 74.00000; 6.94275;103.24170;      75.00000; 0.000000e+000;75.00000; 2.289367e-002;1.01518;4
127.04878; 74.50000; 6.95986;103.17398;      75.00000; 0.000000e+000;75.00000;      -0.35448;1.01673;4
129.55013; 75.00000; 6.97777;103.23147;      75.00000; 0.000000e+000;75.00000;       0.29649;1.01824;4
132.06966; 75.50000; 6.99756;103.16250;      75.00000; 0.000000e+000;75.00000;       0.12178;1.01973;4
134.57148; 76.00000; 7.01811;103.13488;      75.00000; 0.000000e+000;75.00000;      -0.30674;1.02117;4
137.06192; 76.50000; 7.03896;103.23772;      75.00000; 0.000000e+000;75.00000;       0.59324;1.02257;4
139.56896; 77.00000; 7.06448;103.20468;      75.00000; 0.000000e+000;75.00000;       0.27828;1.02394;4
142.10691; 77.50000; 7.08754;103.24709;      75.00000; 0.000000e+000;75.00000;      -1.14167;1.02528;4
144.60648; 78.00000; 7.11093;103.26411;      75.00000; 0.000000e+000;75.00000;      -0.71450;1.02658;4
147.10049; 78.50000; 7.13329;103.21585;      75.00000; 0.000000e+000;75.00000;      -0.22452;1.02783;4
149.60013; 79.00000; 7.15313;103.26874;      75.00000; 0.000000e+000;75.00000;       0.20021;1.02904;4
152.09581; 79.50000; 7.16901;103.31812;      75.00000; 0.000000e+000;75.00000;       0.35197;1.03022;4
154.62100; 80.00000; 7.18525;103.25771;      75.00000; 0.000000e+000;75.00000; 1.123973e-002;1.03137;4
157.11250; 80.50000; 7.20087;103.30442;      75.00000; 0.000000e+000;75.00000;      -0.65894;1.03247;4
159.59764; 81.00000; 7.21668;103.31374;      75.00000; 0.000000e+000;75.00000;       0.22985;1.03353;4
162.09223; 81.50000; 7.23166;103.32160;      75.00000; 0.000000e+000;75.00000;      -0.30770;1.03456;4
164.60817; 82.00000; 7.24573;103.42292;      75.00000; 0.000000e+000;75.00000; 4.257617e-002;1.03555;4
167.11538; 82.50000; 7.25800;103.33676;      75.00000; 0.000000e+000;75.00000; 4.380619e-002;1.03651;4
169.59773; 83.00000; 7.27079;103.35946;      75.00000; 0.000000e+000;75.00000;      -0.23439;1.03741;4
172.10850; 83.50000; 7.28270;103.36901;      75.00000; 0.000000e+000;75.00000;      -0.71654;1.03829;4
174.60800; 84.00000; 7.29678;103.43210;      75.00000; 0.000000e+000;75.00000;       1.12167;1.03913;4
177.12637; 84.50000; 7.30812;103.38870;      75.00000; 0.000000e+000;75.00000;       0.76178;1.03993;4
179.64138; 85.00000; 7.31977;103.40360;      75.00000; 0.000000e+000;75.00000;       0.21492;1.04069;4
182.12320; 85.50000; 7.33218;103.32216;      75.00000; 0.000000e+000;75.00000;       0.57169;1.04141;4
184.64529; 86.00000; 7.34440;103.41947;      75.00000; 0.000000e+000;75.00000;       0.46865;1.04210;4
187.13557; 86.50000; 7.35331;103.46275;      75.00000; 0.000000e+000;75.00000;       0.44642;1.04273;4
189.63000; 87.00000; 7.36357;103.43450;      75.00000; 0.000000e+000;75.00000;       0.54072;1.04334;4
192.13929; 87.50000; 7.37395;103.44517;      75.00000; 0.000000e+000;75.00000;       0.69555;1.04390;4
194.62469; 88.00000; 7.38133;103.48282;      75.00000; 0.000000e+000;75.00000;       0.46132;1.04442;4
197.13618; 88.50000; 7.38843;103.46269;      75.00000; 0.000000e+000;75.00000;      -0.24235;1.04491;4
199.63686; 89.00000; 7.39395;103.48262;      75.00000; 0.000000e+000;75.00000;-3.428513e-002;1.04535;4
202.14464; 89.50000; 7.39812;103.50273;      75.00000; 0.000000e+000;75.00000;       0.23767;1.04576;4
204.65138; 90.00000; 7.40180;103.51030;      75.00000; 0.000000e+000;75.00000;      -0.33942;1.04613;4
207.13943; 90.50000; 7.40970;103.43440;      75.00000; 0.000000e+000;75.00000;       0.99787;1.04645;4
209.63325; 91.00000; 7.42711;103.44510;      75.00000; 0.000000e+000;75.00000;       0.46127;1.04674;4
212.14167; 91.50000; 7.44435;103.44249;      75.00000; 0.000000e+000;75.00000;       0.11118;1.04699;4
214.65222; 92.00000; 7.46425;103.51912;      75.00000; 0.000000e+000;75.00000;       0.50812;1.04720;4
217.12764; 92.50000; 7.48292;103.51859;      75.00000; 0.000000e+000;75.00000;      -0.30969;1.04737;4
219.63333; 93.00000; 7.50518;103.49600;      75.00000; 0.000000e+000;75.00000;      -1.03290;1.04749;4
222.13251; 93.50000; 7.53521;103.49554;      75.00000; 0.000000e+000;75.00000;-7.656641e-002;1.04758;4
224.63269; 94.00000; 7.56268;103.49446;      75.00000; 0.000000e+000;75.00000;       0.60789;1.04763;4
227.13675; 94.50000; 7.58745;103.54175;      75.00000; 0.000000e+000;75.00000;      -0.57094;1.04764;4
229.63848; 95.00000; 7.59099;103.48956;      75.00000; 0.000000e+000;75.00000; 4.924501e-002;1.04761;4
232.14234; 95.50000; 7.61063;103.51597;      75.00000; 0.000000e+000;75.00000;       0.20508;1.04754;4
234.64503; 96.00000; 7.62961;103.51413;      75.00000; 0.000000e+000;75.00000;      -0.18843;1.04743;4
237.13631; 96.50000; 7.64759;103.54127;      75.00000; 0.000000e+000;75.00000;       1.62138;1.04728;4
239.64328; 97.00000; 7.66666;103.52896;      75.00000; 0.000000e+000;75.00000;-9.120757e-002;1.04710;4
242.14317; 97.50000; 7.68457;103.51563;      75.00000; 0.000000e+000;75.00000;       0.64784;1.04687;4
244.64224; 98.00000; 7.70083;103.56872;      75.00000; 0.000000e+000;75.00000;       0.32553;1.04660;4
247.13843; 98.50000; 7.71832;103.55500;      75.00000; 0.000000e+000;75.00000;      -0.60937;1.04629;4
249.65201; 99.00000; 7.73534;103.59729;      75.00000; 0.000000e+000;75.00000;       0.53374;1.04594;4
252.14736; 99.50000; 7.75046;103.64157;      75.00000; 0.000000e+000;75.00000;       0.26373;1.04555;4
254.65516;100.00000; 7.76771;103.70918;      75.00000; 0.000000e+000;75.00000;       0.50303;1.04513;4
257.16506;100.50000; 7.78399;103.67834;      75.00000; 0.000000e+000;75.00000;       0.52919;1.04466;4
259.66024;101.00000; 7.80417;103.67192;      75.00000; 0.000000e+000;75.00000; 8.761198e-002;1.04415;4
262.13918;101.50000; 7.82182;103.69288;      75.00000; 0.000000e+000;75.00000;-1.820986e-002;1.04361;4
264.65838;102.00000; 7.84069;103.68173;      75.00000; 0.000000e+000;75.00000;      -0.27626;1.04302;4
267.15681;102.50000; 7.85664;103.66816;      75.00000; 0.000000e+000;75.00000;      -0.87355;1.04240;4
269.65591;103.00000; 7.87355;103.74248;      75.00000; 0.000000e+000;75.00000;       0.29072;1.04174;4
272.14610;103.50000; 7.89156;103.72758;      75.00000; 0.000000e+000;75.00000;       0.17560;1.04104;4
274.64338;104.00000; 7.90998;103.71562;      75.00000; 0.000000e+000;75.00000;       0.10298;1.04029;4
277.16052;104.50000; 7.92855;103.67774;      75.00000; 0.000000e+000;75.00000;      -1.59716;1.03951;4
279.64895;105.00000; 7.94786;103.65069;      75.00000; 0.000000e+000;75.00000;       0.40656;1.03869;4
282.15115;105.50000; 7.96548;103.68457;      75.00000; 0.000000e+000;75.00000;      -0.45568;1.03783;4
284.66969;106.00000; 7.98582;103.71971;      75.00000; 0.000000e+000;75.00000;      -0.90447;1.03693;4
287.15226;106.50000; 8.00253;103.70940;      75.00000; 0.000000e+000;75.00000; 8.590116e-002;1.03600;4
289.66132;107.00000; 8.02296;103.72109;      75.00000; 0.000000e+000;75.00000;       0.14274;1.03502;4
292.13988;107.50000; 8.03584;103.74523;      75.00000; 0.000000e+000;75.00000;      -1.06216;1.03402;4
294.65563;108.00000; 8.04876;103.77461;      75.00000; 0.000000e+000;75.00000;       0.65970;1.03296;4
297.16051;108.50000; 8.05908;103.75457;      75.00000; 0.000000e+000;75.00000;      -0.58564;1.03187;4
299.66350;109.00000; 8.05741;103.76351;      75.00000; 0.000000e+000;75.00000;-4.727493e-002;1.03074;4
302.15112;109.50000; 8.06777;103.79311;      75.00000; 0.000000e+000;75.00000;      -0.17008;1.02958;4
304.66746;110.00000; 8.07485;103.72167;      75.00000; 0.000000e+000;75.00000;      -0.85233;1.02837;4
307.16413;110.50000; 8.08086;103.73986;      75.00000; 0.000000e+000;75.00000;       0.76915;1.02713;4
309.66132;111.00000; 8.08510;103.76420;      75.00000; 0.000000e+000;75.00000;       0.41164;1.02585;4
312.15389;111.50000; 8.08623;103.75408;      75.00000; 0.000000e+000;75.00000;      -0.35323;1.02454;4
314.65709;112.00000; 8.08500;103.75119;      75.00000; 0.000000e+000;75.00000;      -0.18272;1.02318;4
317.16601;112.50000; 8.08649;103.73713;      75.00000; 0.000000e+000;75.00000;      -0.94873;1.02178;4
319.65620;113.00000; 8.08694;103.68462;      75.00000; 0.000000e+000;75.00000;       0.69315;1.02036;4
322.15244;113.50000; 8.08263;103.65219;      75.00000; 0.000000e+000;75.00000;      -0.15243;1.01890;4
324.67045;114.00000; 8.07577;103.67168;      75.00000; 0.000000e+000;75.00000;      -0.47030;1.01739;4
327.16961;114.50000; 8.06373;103.66914;      75.00000; 0.000000e+000;75.00000;       0.27695;1.01585;4
329.68076;115.00000; 8.05310;103.57576;      75.00000; 0.000000e+000;75.00000;-8.072673e-002;1.01427;4
332.16509;115.50000; 8.04071;103.75855;      75.00000; 0.000000e+000;75.00000;       1.27116;1.01266;4
334.66826;116.00000; 8.02200;103.73614;      75.00000; 0.000000e+000;75.00000;      -0.13118;1.01101;4
337.17994;116.50000; 8.00099;103.74049;      75.00000; 0.000000e+000;75.00000;       0.21944;1.00932;4
339.70008;117.00000; 7.97897;103.58364;      75.00000; 0.000000e+000;75.00000;      -0.18213;1.00759;4
342.20690;117.50000; 7.94826;103.54865;      75.00000; 0.000000e+000;75.00000;       0.57099;1.00583;4
344.69429;118.00000; 7.90450;103.49727;      75.00000; 0.000000e+000;75.00000;       0.25906;1.00405;4
347.18241;118.50000; 7.85300;103.36245;      75.00000; 0.000000e+000;75.00000;      -0.31346;1.00223;4
349.68038;119.00000; 7.78843;103.33336;      75.00000; 0.000000e+000;75.00000;-1.884563e-002;1.00037;4
352.17501;119.50000; 7.71294;103.18951;      75.00000; 0.000000e+000;75.00000;       0.13525;0.99848;4
354.68785;120.00000; 7.63247;103.01721;      75.00000; 0.000000e+000;75.00000;       0.41131;0.99654;4
357.17647;120.50000; 7.54315;102.92043;      75.00000; 0.000000e+000;75.00000;       0.49100;0.99459;4
359.68504;121.00000; 7.44504;102.69423;      75.00000; 0.000000e+000;75.00000;      -1.27664;0.99258;4
362.18191;121.50000; 7.34836;102.56957;      75.00000; 0.000000e+000;75.00000;      -0.17838;0.99056;4
364.68008;122.00000; 7.24685;102.40014;      75.00000; 0.000000e+000;75.00000;      -0.74379;0.98849;4
367.18583;122.50000; 7.14220;102.15461;      75.00000; 0.000000e+000;75.00000; 1.985262e-002;0.98639;4
369.69335;123.00000; 7.03635;101.93913;      75.00000; 0.000000e+000;75.00000;      -1.12170;0.98425;4
372.17796;123.50000; 6.93589;101.68947;      75.00000; 0.000000e+000;75.00000;       0.94252;0.98210;4
374.69615;124.00000; 6.84597;101.40965;      75.00000; 0.000000e+000;75.00000;-6.854779e-002;0.97988;4
377.20912;124.50000; 6.76395;101.16267;      75.00000; 0.000000e+000;75.00000;      -1.03160;0.97764;4
379.68754;125.00000; 6.69675;100.72748;      75.00000; 0.000000e+000;75.00000;      -0.22458;0.97540;4
382.18345;125.50000; 6.64586;100.51337;      75.00000; 0.000000e+000;75.00000;      -0.77928;0.97310;4
384.67352;126.00000; 6.61554;100.24686;      75.00000; 0.000000e+000;75.00000;      -0.61935;0.97079;4
387.17694;126.50000; 6.60795; 99.80736;      75.00000; 0.000000e+000;75.00000;      -0.54701;0.96843;4
389.68237;127.00000; 6.62321; 99.48250;      75.00000; 0.000000e+000;75.00000;      -0.30006;0.96603;4
392.17408;127.50000; 6.66724; 99.15248;      75.00000; 0.000000e+000;75.00000;      -1.48579;0.96362;4
394.67422;128.00000; 6.73338; 98.82748;      75.00000; 0.000000e+000;75.00000;      -1.55820;0.96117;4
397.15922;128.50000; 6.83848; 98.51764;      75.00000; 0.000000e+000;75.00000;      -0.32461;0.95870;4
399.66649;129.00000; 6.96095; 98.14594;      75.00000; 0.000000e+000;75.00000; 1.100221e-002;0.95618;4
402.17856;129.50000; 7.11263; 97.82828;      75.00000; 0.000000e+000;75.00000;      -0.15783;0.95362;4
404.67520;130.00000; 7.29807; 97.49160;      75.00000; 0.000000e+000;75.00000;       0.80614;0.95105;4
407.16774;130.50000; 7.49570; 97.19098;      75.00000; 0.000000e+000;75.00000;      -1.51693;0.94846;4
409.66873;131.00000; 7.70295; 97.00860;      75.00000; 0.000000e+000;75.00000;      -0.19775;0.94583;4
412.17444;131.50000; 7.91947; 96.76069;      75.00000; 0.000000e+000;75.00000; 3.468665e-002;0.94316;4
414.64685;132.00000; 8.13936; 96.62614;      75.00000; 0.000000e+000;75.00000;      -0.97719;0.94050;4
417.15713;132.50000; 8.36041; 96.31249;      75.00000; 0.000000e+000;75.00000; 1.406753e-002;0.93777;4
419.67045;133.00000; 8.58952; 96.15146;      75.00000; 0.000000e+000;75.00000;       0.20593;0.93501;4
422.18217;133.50000; 8.81286; 96.07323;      75.00000; 0.000000e+000;75.00000;-5.883541e-002;0.93223;4
424.68849;134.00000; 9.03365; 95.90190;      75.00000; 0.000000e+000;75.00000;       0.26794;0.92942;4
427.17833;134.50000; 9.24602; 95.75524;      75.00000; 0.000000e+000;75.00000;      -0.82315;0.92660;4
429.67660;135.00000; 9.43545; 95.78256;      75.00000; 0.000000e+000;75.00000;       0.33569;0.92375;4
432.16994;135.50000; 9.61678; 95.68991;      75.00000; 0.000000e+000;75.00000;      -0.79101;0.92088;4
434.68990;136.00000; 9.78918; 95.62192;      75.00000; 0.000000e+000;75.00000;-7.899171e-002;0.91794;4
437.20065;136.50000; 9.95329; 95.61179;      75.00000; 0.000000e+000;75.00000; 7.031177e-002;0.91500;4
439.71598;137.00000;10.09456; 95.59883;      75.00000; 0.000000e+000;75.00000;-4.434843e-002;0.91202;4
442.19647;137.50000;10.22200; 95.61917;      75.00000; 0.000000e+000;75.00000; 3.210146e-002;0.90906;4
444.69572;138.00000;10.33909; 95.59075;      75.00000; 0.000000e+000;75.00000;      -0.38580;0.90605;4
447.19167;138.50000;10.44351; 95.50033;      75.00000; 0.000000e+000;75.00000;       0.78262;0.90301;4
449.69294;139.00000;10.53620; 95.51423;      75.00000; 0.000000e+000;75.00000;       0.73134;0.89995;4
452.17593;139.50000;10.62414; 95.49242;      75.00000; 0.000000e+000;75.00000;      -0.18178;0.89689;4
454.67024;140.00000;10.70069; 95.51495;      75.00000; 0.000000e+000;75.00000;       0.95711;0.89379;4
457.18068;140.50000;10.76939; 95.52228;      75.00000; 0.000000e+000;75.00000;      -0.30411;0.89064;4
459.68216;141.00000;10.84181; 95.54366;      75.00000; 0.000000e+000;75.00000;       1.12373;0.88749;4
462.17068;141.50000;10.90622; 95.45129;      75.00000; 0.000000e+000;75.00000;       0.22965;0.88432;4
464.68609;142.00000;10.96783; 95.51713;      75.00000; 0.000000e+000;75.00000;      -0.33871;0.88110;4
467.17635;142.50000;11.02176; 95.43981;      75.00000; 0.000000e+000;75.00000;      -0.72082;0.87789;4
469.68347;143.00000;11.07739; 95.59833;      75.00000; 0.000000e+000;75.00000;      -0.58546;0.87464;4
472.16250;143.50000;11.14326; 95.57805;      75.00000; 0.000000e+000;75.00000; 6.971809e-002;0.87140;4
474.68690;144.00000;11.20818; 95.53615;      75.00000; 0.000000e+000;75.00000;       0.66355;0.86808;4
477.19282;144.50000;11.27013; 95.56165;      75.00000; 0.000000e+000;75.00000;       0.58403;0.86476;4
479.69191;145.00000;11.33689; 95.52330;      75.00000; 0.000000e+000;75.00000;       0.99371;0.86143;4
482.17951;145.50000;11.39484; 95.53365;      75.00000; 0.000000e+000;75.00000;       0.32734;0.85810;4
484.70055;146.00000;11.46110; 95.55983;      75.00000; 0.000000e+000;75.00000;       0.40039;0.85470;4
487.17877;146.50000;11.53513; 95.55454;      75.00000; 0.000000e+000;75.00000;       0.39669;0.85134;4
489.68670;147.00000;11.60745; 95.63080;      75.00000; 0.000000e+000;75.00000; 7.084441e-002;0.84792;4
492.19925;147.50000;11.68432; 95.63931;      75.00000; 0.000000e+000;75.00000;      -0.26462;0.84447;4
494.69857;148.00000;11.76628; 95.63379;      75.00000; 0.000000e+000;75.00000;       0.53689;0.84102;4
497.19147;148.50000;11.84396; 95.65067;      75.00000; 0.000000e+000;75.00000;       0.23741;0.83757;4
499.70578;149.00000;11.92257; 95.69371;      75.00000; 0.000000e+000;75.00000;      -0.25312;0.83406;4
502.19009;149.50000;12.00405; 95.65394;      75.00000; 0.000000e+000;75.00000;       0.46947;0.83058;4
504.69760;150.00000;12.08569; 95.68791;      75.00000; 0.000000e+000;75.00000;       0.33932;0.82705;4
507.20031;150.50000;12.16918; 95.64371;      75.00000; 0.000000e+000;75.00000;       0.62280;0.82351;4
509.67701;151.00000;12.25196; 95.68598;      75.00000; 0.000000e+000;75.00000;      -0.51924;0.81999;4
512.19767;151.50000;12.33403; 95.65655;      75.00000; 0.000000e+000;75.00000;       0.10602;0.81639;4
514.69754;152.00000;12.41189; 95.67535;      75.00000; 0.000000e+000;75.00000;       0.37247;0.81281;4
517.19416;152.50000;12.49520; 95.66342;      75.00000; 0.000000e+000;75.00000;       0.16006;0.80921;4
519.69935;153.00000;12.57930; 95.69603;      75.00000; 0.000000e+000;75.00000;       1.15629;0.80559;4
522.19380;153.50000;12.66040; 95.79669;      75.00000; 0.000000e+000;75.00000;      -0.11878;0.80196;4
524.69024;154.00000;12.74508; 95.90494;      75.00000; 0.000000e+000;75.00000;      -1.43812;0.79832;4
527.19800;154.50000;12.83397; 95.80171;      75.00000; 0.000000e+000;75.00000;       0.34807;0.79465;4
529.69781;155.00000;12.91976; 95.77169;      75.00000; 0.000000e+000;75.00000; 7.052663e-002;0.79098;4
532.18356;155.50000;13.01415; 95.76453;      75.00000; 0.000000e+000;75.00000;      -0.56190;0.78731;4
534.70671;156.00000;13.10433; 95.80797;      75.00000; 0.000000e+000;75.00000;       0.56769;0.78357;4
537.22363;156.50000;13.19633; 95.86557;      75.00000; 0.000000e+000;75.00000;       0.33129;0.77983;4
539.70390;157.00000;13.28958; 95.85801;      75.00000; 0.000000e+000;75.00000;      -0.61234;0.77614;4
542.19876;157.50000;13.38805; 95.83714;      75.00000; 0.000000e+000;75.00000;      -0.13518;0.77240;4
544.71383;158.00000;13.48142; 95.83289;      75.00000; 0.000000e+000;75.00000; 2.883993e-002;0.76863;4
547.20692;158.50000;13.58162; 95.89313;      75.00000; 0.000000e+000;75.00000;      -0.53607;0.76488;4
549.72865;159.00000;13.68247; 95.90755;      75.00000; 0.000000e+000;75.00000;      -0.11960;0.76107;4
552.21017;159.50000;13.78141; 95.88100;      75.00000; 0.000000e+000;75.00000;-7.366739e-003;0.75731;4
554.72845;160.00000;13.88081; 95.88766;      75.00000; 0.000000e+000;75.00000;       0.27130;0.75349;4
557.22109;160.50000;13.98276; 95.89274;      75.00000; 0.000000e+000;75.00000;      -0.49780;0.74970;4
559.71099;161.00000;14.09034; 95.90489;      75.00000; 0.000000e+000;75.00000;       1.00461;0.74590;4
562.21240;161.50000;14.20143; 95.88812;      75.00000; 0.000000e+000;75.00000;-4.607529e-002;0.74207;4
564.71470;162.00000;14.31166; 95.90032;      75.00000; 0.000000e+000;75.00000;      -0.75787;0.73823;4
567.22250;162.50000;14.42072; 95.92536;      75.00000; 0.000000e+000;75.00000;       1.18764;0.73437;4
569.72171;163.00000;14.53960; 95.89734;      75.00000; 0.000000e+000;75.00000;       0.47435;0.73052;4
572.23632;163.50000;14.65812; 95.85830;      75.00000; 0.000000e+000;75.00000;-1.423293e-003;0.72664;4
574.71491;164.00000;14.77419; 95.90230;      75.00000; 0.000000e+000;75.00000;      -0.20640;0.72281;4
577.22415;164.50000;14.88930; 95.89493;      75.00000; 0.000000e+000;75.00000;       0.30186;0.71892;4
579.73449;165.00000;15.01142; 95.88256;      75.00000; 0.000000e+000;75.00000;       0.37398;0.71502;4
582.22878;165.50000;15.12829; 95.91837;      75.00000; 0.000000e+000;75.00000;-4.244174e-002;0.71114;4
584.72268;166.00000;15.25626; 95.84994;      75.00000; 0.000000e+000;75.00000;      -0.19311;0.70725;4
587.23921;166.50000;15.37625; 95.81408;      75.00000; 0.000000e+000;75.00000;      -0.20024;0.70332;4
589.73422;167.00000;15.50681; 95.89136;      75.00000; 0.000000e+000;75.00000;       0.43778;0.69942;4
592.23704;167.50000;15.63457; 95.77969;      75.00000; 0.000000e+000;75.00000;      -0.11430;0.69550;4
594.73933;168.00000;15.76021; 95.83758;      75.00000; 0.000000e+000;75.00000;       0.41555;0.69158;4
597.24605;168.50000;15.88343; 95.90084;      75.00000; 0.000000e+000;75.00000;       0.42771;0.68764;4
599.73616;169.00000;16.01345; 95.86164;      75.00000; 0.000000e+000;75.00000;      -0.78384;0.68373;4
602.24493;169.50000;16.14382; 95.89541;      75.00000; 0.000000e+000;75.00000;      -1.17224;0.67978;4
604.74422;170.00000;16.27280; 95.85142;      75.00000; 0.000000e+000;75.00000;       0.12003;0.67585;4
607.23641;170.50000;16.41358; 95.73586;      75.00000; 0.000000e+000;75.00000;      -1.21177;0.67192;4
609.74603;171.00000;16.53743; 95.87803;      75.00000; 0.000000e+000;75.00000;      -0.42795;0.66796;4
612.23716;171.50000;16.66843; 95.89324;      75.00000; 0.000000e+000;75.00000;       1.34403;0.66403;4
614.75385;172.00000;16.81142; 95.85359;      75.00000; 0.000000e+000;75.00000;      -0.96075;0.66005;4
617.25126;172.50000;16.94929; 95.89607;      75.00000; 0.000000e+000;75.00000;      -0.24924;0.65611;4
619.75053;173.00000;17.08478; 95.86153;      75.00000; 0.000000e+000;75.00000;       0.26200;0.65215;4
622.23358;173.50000;17.23073; 95.89089;      75.00000; 0.000000e+000;75.00000;-7.148392e-002;0.64823;4
624.73684;174.00000;17.37483; 95.82072;      75.00000; 0.000000e+000;75.00000;-1.919954e-002;0.64426;4
627.24444;174.50000;17.52331; 95.88302;      75.00000; 0.000000e+000;75.00000;       0.53652;0.64029;4
629.73461;175.00000;17.67974; 95.87780;      75.00000; 0.000000e+000;75.00000;       0.74795;0.63635;4
632.23876;175.50000;17.82056; 95.91135;      75.00000; 0.000000e+000;75.00000;       0.10760;0.63239;4
634.75083;176.00000;17.98274; 95.90490;      75.00000; 0.000000e+000;75.00000;       0.22587;0.62841;4
637.23189;176.50000;18.14453; 95.91034;      75.00000; 0.000000e+000;75.00000;       0.47587;0.62448;4
639.72763;177.00000;18.30084; 95.87798;      75.00000; 0.000000e+000;75.00000;       0.43297;0.62053;4
642.23308;177.50000;18.46190; 95.90082;      75.00000; 0.000000e+000;75.00000;       0.62250;0.61656;4
644.74488;178.00000;18.62426; 95.93201;      75.00000; 0.000000e+000;75.00000;       0.25580;0.61259;4
647.24224;178.50000;18.78952; 95.95330;      75.00000; 0.000000e+000;75.00000;       0.39997;0.60863;4
649.74347;179.00000;18.96156; 95.97379;      75.00000; 0.000000e+000;75.00000;      -0.69019;0.60468;4
652.23132;179.50000;19.12915; 96.01771;      75.00000; 0.000000e+000;75.00000;      -0.76607;0.60075;4
654.73588;180.00000;19.30511; 96.00019;      75.00000; 0.000000e+000;75.00000;       0.55065;0.59679;4
657.23435;180.50000;19.47430; 96.00452;      75.00000; 0.000000e+000;75.00000;      -0.24829;0.59285;4
659.73304;181.00000;19.65047; 96.07458;      75.00000; 0.000000e+000;75.00000;      -0.42463;0.58890;4
662.24052;181.50000;19.82561; 96.08138;      75.00000; 0.000000e+000;75.00000;       0.24051;0.58495;4
664.73722;182.00000;20.00571; 96.06509;      75.00000; 0.000000e+000;75.00000;       1.12440;0.58102;4
667.24606;182.50000;20.18460; 96.09383;      75.00000; 0.000000e+000;75.00000;      -1.74036;0.57707;4
669.75291;183.00000;20.37290; 96.10746;      75.00000; 0.000000e+000;75.00000;       0.37742;0.57313;4
672.24549;183.50000;20.56488; 96.19419;      75.00000; 0.000000e+000;75.00000;       2.06970;0.56922;4
674.75295;184.00000;20.75796; 96.18438;      75.00000; 0.000000e+000;75.00000; 6.323652e-003;0.56528;4
677.24171;184.50000;20.94861; 96.17943;      75.00000; 0.000000e+000;75.00000;      -0.12052;0.56138;4
679.74444;185.00000;21.14594; 96.16742;      75.00000; 0.000000e+000;75.00000;      -0.65743;0.55747;4
682.25812;185.50000;21.34054; 96.21907;      75.00000; 0.000000e+000;75.00000;       1.52007;0.55354;4
684.74841;186.00000;21.54282; 96.24650;      75.00000; 0.000000e+000;75.00000;       0.16428;0.54966;4
687.24944;186.50000;21.73036; 96.29742;      75.00000; 0.000000e+000;75.00000;       1.09089;0.54576;4
689.76054;187.00000;21.94451; 96.27422;      75.00000; 0.000000e+000;75.00000;       0.24849;0.54185;4
692.26643;187.50000;22.14433; 96.32331;      75.00000; 0.000000e+000;75.00000;-2.901646e-002;0.53796;4
694.75577;188.00000;22.34833; 96.32047;      75.00000; 0.000000e+000;75.00000;       0.19856;0.53410;4
697.27094;188.50000;22.56634; 96.36390;      75.00000; 0.000000e+000;75.00000;       0.65187;0.53021;4
699.75432;189.00000;22.77151; 96.38676;      75.00000; 0.000000e+000;75.00000;       1.56588;0.52637;4